Workbook

Sheet Menu
H12: Detalhes da Copa do Mundo 2026
I13: 5182
H15: 48 seleções nacionais confirmadas
H16: Estreantes: Cabo Verde, Curaçao, Haiti, Jordânia e Uzbequistão
H18: UEFA (Europa): 16 países
H19: CAF (África): 9 países
H20: AFC (Ásia): 8 países
H21: CONMEBOL (América do Sul): 6 países
H22: CONCACAF (América do Norte, Central e Caribe): 6 países
H23: OFC (Oceania): 1 país
H25: Cada seleção pode registrar no mínimo 23 e no máximo 26 jogadores.
H26: Estimativa de 1.104 à 1248 jogadores.
I31: 🥇 | J31: Campeão
I32: 🥈 | J32: Vice-Campeão
I33: 🥉 | J33: 3º Lugar

Sheet Classificados
B1: 2026 FIFA World Cup - Classificados
D3: Times | G3: Vagas | H3: Restantes
C4: 1 | D4: Canadá | E4: Anfitrião | G4: 48 | H4: =COUNTBLANK(Tabela1[Times]) -> 0
C5: 2 | D5: México | E5: Anfitrião
C6: 3 | D6: Estados Unidos | E6: Anfitrião
C7: 4 | D7: Japão | E7: AFC
C8: 5 | D8: Irã | E8: AFC
C9: 6 | D9: Uzbequistão | E9: AFC
C10: 7 | D10: Coreia do Sul | E10: AFC
C11: 8 | D11: Jordânia | E11: AFC
C12: 9 | D12: Austrália | E12: AFC
C13: 10 | D13: Qatar | E13: AFC
C14: 11 | D14: Arabia Saudita | E14: AFC
C15: 12 | D15: Marrocos | E15: CAF
C16: 13 | D16: Tunisia | E16: CAF
... C51: 48 | D51: Iraque | E51: Repescagem

Sheet Sorteios
B1: 2026 FIFA World Cup - Sorteios
B4: Grupo A | E4: Grupo B | H4: Grupo C
B5: P. | C5: Seleção | E5: P. | F5: Seleção | H5: P. | I5: Seleção
B6: 1 | C6: México | E6: 1 | F6: Canadá | H6: 1 | I6: Brasil
B7: 2 | C7: África do Sul | E7: 2 | F7: Bósnia | H7: 2 | I7: Marrocos
B8: 3 | C8: Coreia do Sul | E8: 3 | F8: Qatar | H8: 3 | I8: Haiti
B9: 4 | C9: República Tcheca | E9: 4 | F9: Suiça | H9: 4 | I9: Escócia
B12: Grupo D | E12: Grupo E | H12: Grupo F
B13: P. | C13: Seleção | E13: P. | F13: Seleção | H13: P. | I13: Seleção
B14: 1 | C14: Estados Unidos | E14: 1 | F14: Alemanha | H14: 1 | I14: Países Baixos
B15: 2 | C15: Paraguai | E15: 2 | F15: Curaçau | H15: 2 | I15: Japão
B16: 3 | C16: Austrália | E16: 3 | F16: Costa do Marfim | H16: 3 | I16: Suécia
B17: 4 | C17: Turquia | E17: 4 | F17: Equador | H17: 4 | I17: Tunísia
B20: Grupo G | E20: Grupo H | H20: Grupo I
B21: P. | C21: Seleção | E21: P. | F21: Seleção | H21: P. | I21: Seleção
B22: 1 | C22: Bélgica | E22: 1 | F22: Espanha | H22: 1 | I22: França
B23: 2 | C23: Egito | E23: 2 | F23: Cabo Verde | H23: 2 | I23: Senegal
B24: 3 | C24: Irã | E24: 3 | F24: Arábia Saudita | H24: 3 | I24: Iraque
B25: 4 | C25: Nova Zelândia | E25: 4 | F25: Uruguai | H25: 4 | I25: Noruega
B28: Grupo J | E28: Grupo K | H28: Grupo L
B29: P. | C29: Seleção | E29: P. | F29: Seleção | H29: P. | I29: Seleção
B30: 1 | C30: Argentina | E30: 1 | F30: Portugal | H30: 1 | I30: Inglaterra
B31: 2 | C31: Argélia | E31: 2 | F31: RD Congo | H31: 2 | I31: Croácia
B32: 3 | C32: Áustria | E32: 3 | F32: Uzbequistão | H32: 3 | I32: Gana
B33: 4 | C33: Jordânia | E33: 4 | F33: Colômbia | H33: 4 | I33: Panamá

Sheet Fase de Grupos
B1: 2026 FIFA World Cup - Fase de Grupos
B3: Gr. | C3: Data | D3: Hora | E3: Seleção | F3: Placar | I3: Seleção | P3: Grupos | AE3: Grupos
B4: A | C4: 46184 | D4: 12.00 | E4: =P6 -> México | F4: 2 | G4: x | H4: 0 | I4: =P7 -> África do Sul | J4: =IF(F4=H4,"empate",IF(F4>H4,E4,I4)) -> México | K4: =IF(F4="","",IF(H4="","",IF(J4="empate",E4,""))) | L4: =IF(E4="","",IF(F4="","",IF(M4="empate",I4,""))) | M4: =IF(F4=H4,"empate",IF(F4<H4,E4,I4)) -> África do Sul | P4: Grupo A | AE4: Grupo A | BI4: Melhores 3ºs Colocados
B5: A | C5: 46184 | D5: 09.00 | E5: =P8 -> Coreia do Sul | F5: 2 | G5: x | H5: 1 | I5: =P9 -> República Tcheca | J5: =IF(F5=H5,"empate",IF(F5>H5,E5,I5)) -> Coreia do Sul | K5: =IF(F5="","",IF(H5="","",IF(J5="empate",E5,""))) | L5: =IF(E5="","",IF(F5="","",IF(M5="empate",I5,""))) | M5: =IF(F5=H5,"empate",IF(F5<H5,E5,I5)) -> República Tcheca | O5: Rk | P5: Sorteio | Q5: Pontos | R5: Jogos | S5: Vit | T5: Emp | U5: Der | V5: GP | W5: GC | X5: SG | Y5: SAL | Z5: PRO | AA5: CON | AB5: NM | AC5: Or. | AE5: P. | AF5: Seleção | AG5: P | AH5: J | AI5: V | AJ5: E | AK5: D | AL5: GP | AM5: GC | AN5: SG | AP5: Rk | AQ5: Seleção | AR5: Pontos | AS5: Jogos | AT5: Vit | AU5: Emp | AV5: Der | AW5: GP | AX5: GC | AY5: SG | BB5: SAL | BC5: PRO | BD5: CON | BE5: NM | BF5: Or. | BI5: P. | BJ5: Seleção | BK5: P | BL5: J | BM5: V | BN5: E | BO5: D | BP5: GP | BQ5: GC | BR5: SG
B6: A | C6: 46191 | D6: 15.00 | E6: =P6 -> México | F6: 1 | G6: x | H6: 0 | I6: =P8 -> Coreia do Sul | J6: =IF(F6=H6,"empate",IF(F6>H6,E6,I6)) -> México | K6: =IF(F6="","",IF(H6="","",IF(J6="empate",E6,""))) | L6: =IF(E6="","",IF(F6="","",IF(M6="empate",I6,""))) | M6: =IF(F6=H6,"empate",IF(F6<H6,E6,I6)) -> Coreia do Sul | O6: =RANK(Q6,$Q$6:$Q$9)+SUM(Y6:AB6) -> 1 | P6: =Sorteios!C6 -> México | Q6: =(S6*3)+(T6*1) -> 9 | R6: =SUM(S6:U6) -> 3 | S6: =COUNTIF(J:J,P6) -> 3 | T6: =COUNTIF(K:K,P6)+COUNTIF(L:L,P6) -> 0 | U6: =COUNTIF(M:M,P6) -> 0 | V6: =SUMIF(E:E,P6,F:F)+SUMIF(I:I,P6,H:H) -> 6 | W6: =SUMIF(E:E,P6,H:H)+SUMIF(I:I,P6,F:F) -> 0 | X6: =V6-W6 -> 6 | Y6: =SUMPRODUCT(($Q$6:$Q$9=Q6)*($X$6:$X$9>X6)) -> 0 | Z6: =SUMPRODUCT(($Q$6:$Q$9=Q6)*($X$6:$X$9=X6)*($V$6:$V$9>V6)) -> 0 | AA6: =SUMPRODUCT(($Q$6:$Q$9=Q6)*($X$6:$X$9=X6)*($V$6:$V$9=V6)*($W$6:$W$9>W6)) -> 0 | AB6: =SUMPRODUCT(($Q$6:$Q$9=Q6)*($X$6:$X$9=X6)*($V$6:$V$9=V6)*($W$6:$W$9=W6)*($AC$6:$AC$9<AC6)) -> 0 | AC6: 1 | AE6: 1 | AF6: =VLOOKUP($AE6,$O$6:$X$9,2,FALSE) -> México | AG6: =VLOOKUP($AE6,$O$6:$X$9,3,FALSE) -> 9 | AH6: =VLOOKUP($AE6,$O$6:$X$9,4,FALSE) -> 3 | AI6: =VLOOKUP($AE6,$O$6:$X$9,5,FALSE) -> 3 | AJ6: =VLOOKUP($AE6,$O$6:$X$9,6,FALSE) -> 0 | AK6: =VLOOKUP($AE6,$O$6:$X$9,7,FALSE) -> 0 | AL6: =VLOOKUP($AE6,$O$6:$X$9,8,FALSE) -> 6 | AM6: =VLOOKUP($AE6,$O$6:$X$9,9,FALSE) -> 0 | AN6: =VLOOKUP($AE6,$O$6:$X$9,10,FALSE) -> 6 | AP6: =RANK(AR6,$AR$6:$AR$17)+SUM(BB6:BE6) -> 10 | AQ6: =AF8 -> Coreia do Sul | AR6: =(AT6*3)+(AU6*1) -> 3 | AS6: =SUM(AT6:AV6) -> 3 | AT6: =VLOOKUP(AQ6,$P$5:$X$75,4,FALSE) -> 1 | AU6: =VLOOKUP(AQ6,$P$5:$X$75,5,FALSE) -> 0 | AV6: =VLOOKUP(AQ6,$P$5:$X$75,6,FALSE) -> 2 | AW6: =VLOOKUP(AQ6,$P$5:$X$75,7,FALSE) -> 2 | AX6: =VLOOKUP(AQ6,$P$5:$X$75,8,FALSE) -> 3 | AY6: =AW6-AX6 -> -1 | AZ6: A | BA6: =AQ6 -> Coreia do Sul | BB6: =SUMPRODUCT(($AR$6:$AR$17=AR6)*($AY$6:$AY$17>AY6)) -> 2 | BC6: =SUMPRODUCT(($AR$6:$AR$17=AR6)*($AY$6:$AY$17=AY6)*($AW$6:$AW$17>AW6)) -> 0 | BD6: =SUMPRODUCT(($AR$6:$AR$17=AR6)*($AY$6:$AY$17=AY6)*($AW$6:$AW$17=AW6)*($AX$6:$AX$17>AX6)) -> 0 | BE6: =SUMPRODUCT(($AR$6:$AR$17=AR6)*($AY$6:$AY$17=AY6)*($AW$6:$AW$17=AW6)*($AX$6:$AX$17=AX6)*($BF$6:$BF$17<BF6)) -> 0 | BF6: 1 | BI6: 1 | BJ6: =VLOOKUP($BI6,$AP$6:$AY$17,2,FALSE) -> RD Congo | BK6: =VLOOKUP($BI6,$AP$6:$AY$17,3,FALSE) -> 4 | BL6: =VLOOKUP($BI6,$AP$6:$AY$17,4,FALSE) -> 3 | BM6: =VLOOKUP($BI6,$AP$6:$AY$17,5,FALSE) -> 1 | BN6: =VLOOKUP($BI6,$AP$6:$AY$17,6,FALSE) -> 1 | BO6: =VLOOKUP($BI6,$AP$6:$AY$17,7,FALSE) -> 1 | BP6: =VLOOKUP($BI6,$AP$6:$AY$17,8,FALSE) -> 4 | BQ6: =VLOOKUP($BI6,$AP$6:$AY$17,9,FALSE) -> 3 | BR6: =VLOOKUP($BI6,$AP$6:$AY$17,10,FALSE) -> 1
B7: A | C7: 46191 | D7: 12.00 | E7: =P9 -> República Tcheca | F7: 1 | G7: x | H7: 1 | I7: =P7 -> África do Sul | J7: =IF(F7=H7,"empate",IF(F7>H7,E7,I7)) -> empate | K7: =IF(F7="","",IF(H7="","",IF(J7="empate",E7,""))) -> República Tcheca | L7: =IF(E7="","",IF(F7="","",IF(M7="empate",I7,""))) -> África do Sul | M7: =IF(F7=H7,"empate",IF(F7<H7,E7,I7)) -> empate | O7: =RANK(Q7,$Q$6:$Q$9)+SUM(Y7:AB7) -> 2 | P7: =Sorteios!C7 -> África do Sul | Q7: =(S7*3)+(T7*1) -> 4 | R7: =SUM(S7:U7) -> 3 | S7: =COUNTIF(J:J,P7) -> 1 | T7: =COUNTIF(K:K,P7)+COUNTIF(L:L,P7) -> 1 | U7: =COUNTIF(M:M,P7) -> 1 | V7: =SUMIF(E:E,P7,F:F)+SUMIF(I:I,P7,H:H) -> 2 | W7: =SUMIF(E:E,P7,H:H)+SUMIF(I:I,P7,F:F) -> 3 | X7: =V7-W7 -> -1 | Y7: =SUMPRODUCT(($Q$6:$Q$9=Q7)*($X$6:$X$9>X7)) -> 0 | Z7: =SUMPRODUCT(($Q$6:$Q$9=Q7)*($X$6:$X$9=X7)*($V$6:$V$9>V7)) -> 0 | AA7: =SUMPRODUCT(($Q$6:$Q$9=Q7)*($X$6:$X$9=X7)*($V$6:$V$9=V7)*($W$6:$W$9>W7)) -> 0 | AB7: =SUMPRODUCT(($Q$6:$Q$9=Q7)*($X$6:$X$9=X7)*($V$6:$V$9=V7)*($W$6:$W$9=W7)*($AC$6:$AC$9<AC7)) -> 0 | AC7: 2 | AE7: 2 | AF7: =VLOOKUP($AE7,$O$6:$X$9,2,FALSE) -> África do Sul | AG7: =VLOOKUP($AE7,$O$6:$X$9,3,FALSE) -> 4 | AH7: =VLOOKUP($AE7,$O$6:$X$9,4,FALSE) -> 3 | AI7: =VLOOKUP($AE7,$O$6:$X$9,5,FALSE) -> 1 | AJ7: =VLOOKUP($AE7,$O$6:$X$9,6,FALSE) -> 1 | AK7: =VLOOKUP($AE7,$O$6:$X$9,7,FALSE) -> 1 | AL7: =VLOOKUP($AE7,$O$6:$X$9,8,FALSE) -> 2 | AM7: =VLOOKUP($AE7,$O$6:$X$9,9,FALSE) -> 3 | AN7: =VLOOKUP($AE7,$O$6:$X$9,10,FALSE) -> -1 | AP7: =RANK(AR7,$AR$6:$AR$17)+SUM(BB7:BE7) -> 5 | AQ7: =AF14 -> Bósnia | AR7: =(AT7*3)+(AU7*1) -> 4 | AS7: =SUM(AT7:AV7) -> 3 | AT7: =VLOOKUP(AQ7,$P$5:$X$75,4,FALSE) -> 1 | AU7: =VLOOKUP(AQ7,$P$5:$X$75,5,FALSE) -> 1 | AV7: =VLOOKUP(AQ7,$P$5:$X$75,6,FALSE) -> 1 | AW7: =VLOOKUP(AQ7,$P$5:$X$75,7,FALSE) -> 5 | AX7: =VLOOKUP(AQ7,$P$5:$X$75,8,FALSE) -> 6 | AY7: =AW7-AX7 -> -1 | AZ7: B | BA7: =AQ7 -> Bósnia | BB7: =SUMPRODUCT(($AR$6:$AR$17=AR7)*($AY$6:$AY$17>AY7)) -> 4 | BC7: =SUMPRODUCT(($AR$6:$AR$17=AR7)*($AY$6:$AY$17=AY7)*($AW$6:$AW$17>AW7)) -> 0 | BD7: =SUMPRODUCT(($AR$6:$AR$17=AR7)*($AY$6:$AY$17=AY7)*($AW$6:$AW$17=AW7)*($AX$6:$AX$17>AX7)) -> 0 | BE7: =SUMPRODUCT(($AR$6:$AR$17=AR7)*($AY$6:$AY$17=AY7)*($AW$6:$AW$17=AW7)*($AX$6:$AX$17=AX7)*($BF$6:$BF$17<BF7)) -> 0 | BF7: 2 | BI7: 2 | BJ7: =VLOOKUP($BI7,$AP$6:$AY$17,2,FALSE) -> Suécia | BK7: =VLOOKUP($BI7,$AP$6:$AY$17,3,FALSE) -> 4 | BL7: =VLOOKUP($BI7,$AP$6:$AY$17,4,FALSE) -> 3 | BM7: =VLOOKUP($BI7,$AP$6:$AY$17,5,FALSE) -> 1 | BN7: =VLOOKUP($BI7,$AP$6:$AY$17,6,FALSE) -> 1 | BO7: =VLOOKUP($BI7,$AP$6:$AY$17,7,FALSE) -> 1 | BP7: =VLOOKUP($BI7,$AP$6:$AY$17,8,FALSE) -> 7 | BQ7: =VLOOKUP($BI7,$AP$6:$AY$17,9,FALSE) -> 7 | BR7: =VLOOKUP($BI7,$AP$6:$AY$17,10,FALSE) -> 0
B8: A | C8: 46197 | D8: 11.00 | E8: =P9 -> República Tcheca | F8: 0 | G8: x | H8: 3 | I8: =P6 -> México | J8: =IF(F8=H8,"empate",IF(F8>H8,E8,I8)) -> México | K8: =IF(F8="","",IF(H8="","",IF(J8="empate",E8,""))) | L8: =IF(E8="","",IF(F8="","",IF(M8="empate",I8,""))) | M8: =IF(F8=H8,"empate",IF(F8<H8,E8,I8)) -> República Tcheca | O8: =RANK(Q8,$Q$6:$Q$9)+SUM(Y8:AB8) -> 3 | P8: =Sorteios!C8 -> Coreia do Sul | Q8: =(S8*3)+(T8*1) -> 3 | R8: =SUM(S8:U8) -> 3 | S8: =COUNTIF(J:J,P8) -> 1 | T8: =COUNTIF(K:K,P8)+COUNTIF(L:L,P8) -> 0 | U8: =COUNTIF(M:M,P8) -> 2 | V8: =SUMIF(E:E,P8,F:F)+SUMIF(I:I,P8,H:H) -> 2 | W8: =SUMIF(E:E,P8,H:H)+SUMIF(I:I,P8,F:F) -> 3 | X8: =V8-W8 -> -1 | Y8: =SUMPRODUCT(($Q$6:$Q$9=Q8)*($X$6:$X$9>X8)) -> 0 | Z8: =SUMPRODUCT(($Q$6:$Q$9=Q8)*($X$6:$X$9=X8)*($V$6:$V$9>V8)) -> 0 | AA8: =SUMPRODUCT(($Q$6:$Q$9=Q8)*($X$6:$X$9=X8)*($V$6:$V$9=V8)*($W$6:$W$9>W8)) -> 0 | AB8: =SUMPRODUCT(($Q$6:$Q$9=Q8)*($X$6:$X$9=X8)*($V$6:$V$9=V8)*($W$6:$W$9=W8)*($AC$6:$AC$9<AC8)) -> 0 | AC8: 3 | AE8: 3 | AF8: =VLOOKUP($AE8,$O$6:$X$9,2,FALSE) -> Coreia do Sul | AG8: =VLOOKUP($AE8,$O$6:$X$9,3,FALSE) -> 3 | AH8: =VLOOKUP($AE8,$O$6:$X$9,4,FALSE) -> 3 | AI8: =VLOOKUP($AE8,$O$6:$X$9,5,FALSE) -> 1 | AJ8: =VLOOKUP($AE8,$O$6:$X$9,6,FALSE) -> 0 | AK8: =VLOOKUP($AE8,$O$6:$X$9,7,FALSE) -> 2 | AL8: =VLOOKUP($AE8,$O$6:$X$9,8,FALSE) -> 2 | AM8: =VLOOKUP($AE8,$O$6:$X$9,9,FALSE) -> 3 | AN8: =VLOOKUP($AE8,$O$6:$X$9,10,FALSE) -> -1 | AP8: =RANK(AR8,$AR$6:$AR$17)+SUM(BB8:BE8) -> 11 | AQ8: =AF20 -> Escócia | AR8: =(AT8*3)+(AU8*1) -> 3 | AS8: =SUM(AT8:AV8) -> 3 | AT8: =VLOOKUP(AQ8,$P$5:$X$75,4,FALSE) -> 1 | AU8: =VLOOKUP(AQ8,$P$5:$X$75,5,FALSE) -> 0 | AV8: =VLOOKUP(AQ8,$P$5:$X$75,6,FALSE) -> 2 | AW8: =VLOOKUP(AQ8,$P$5:$X$75,7,FALSE) -> 1 | AX8: =VLOOKUP(AQ8,$P$5:$X$75,8,FALSE) -> 4 | AY8: =AW8-AX8 -> -3 | AZ8: C | BA8: =AQ8 -> Escócia | BB8: =SUMPRODUCT(($AR$6:$AR$17=AR8)*($AY$6:$AY$17>AY8)) -> 3 | BC8: =SUMPRODUCT(($AR$6:$AR$17=AR8)*($AY$6:$AY$17=AY8)*($AW$6:$AW$17>AW8)) -> 0 | BD8: =SUMPRODUCT(($AR$6:$AR$17=AR8)*($AY$6:$AY$17=AY8)*($AW$6:$AW$17=AW8)*($AX$6:$AX$17>AX8)) -> 0 | BE8: =SUMPRODUCT(($AR$6:$AR$17=AR8)*($AY$6:$AY$17=AY8)*($AW$6:$AW$17=AW8)*($AX$6:$AX$17=AX8)*($BF$6:$BF$17<BF8)) -> 0 | BF8: 3 | BI8: 3 | BJ8: =VLOOKUP($BI8,$AP$6:$AY$17,2,FALSE) -> Equador | BK8: =VLOOKUP($BI8,$AP$6:$AY$17,3,FALSE) -> 4 | BL8: =VLOOKUP($BI8,$AP$6:$AY$17,4,FALSE) -> 3 | BM8: =VLOOKUP($BI8,$AP$6:$AY$17,5,FALSE) -> 1 | BN8: =VLOOKUP($BI8,$AP$6:$AY$17,6,FALSE) -> 1 | BO8: =VLOOKUP($BI8,$AP$6:$AY$17,7,FALSE) -> 1 | BP8: =VLOOKUP($BI8,$AP$6:$AY$17,8,FALSE) -> 2 | BQ8: =VLOOKUP($BI8,$AP$6:$AY$17,9,FALSE) -> 2 | BR8: =VLOOKUP($BI8,$AP$6:$AY$17,10,FALSE) -> 0
B9: A | C9: 46197 | D9: 11.00 | E9: =P7 -> África do Sul | F9: 1 | G9: x | H9: 0 | I9: =P8 -> Coreia do Sul | J9: =IF(F9=H9,"empate",IF(F9>H9,E9,I9)) -> África do Sul | K9: =IF(F9="","",IF(H9="","",IF(J9="empate",E9,""))) | L9: =IF(E9="","",IF(F9="","",IF(M9="empate",I9,""))) | M9: =IF(F9=H9,"empate",IF(F9<H9,E9,I9)) -> Coreia do Sul | O9: =RANK(Q9,$Q$6:$Q$9)+SUM(Y9:AB9) -> 4 | P9: =Sorteios!C9 -> República Tcheca | Q9: =(S9*3)+(T9*1) -> 1 | R9: =SUM(S9:U9) -> 3 | S9: =COUNTIF(J:J,P9) -> 0 | T9: =COUNTIF(K:K,P9)+COUNTIF(L:L,P9) -> 1 | U9: =COUNTIF(M:M,P9) -> 2 | V9: =SUMIF(E:E,P9,F:F)+SUMIF(I:I,P9,H:H) -> 2 | W9: =SUMIF(E:E,P9,H:H)+SUMIF(I:I,P9,F:F) -> 6 | X9: =V9-W9 -> -4 | Y9: =SUMPRODUCT(($Q$6:$Q$9=Q9)*($X$6:$X$9>X9)) -> 0 | Z9: =SUMPRODUCT(($Q$6:$Q$9=Q9)*($X$6:$X$9=X9)*($V$6:$V$9>V9)) -> 0 | AA9: =SUMPRODUCT(($Q$6:$Q$9=Q9)*($X$6:$X$9=X9)*($V$6:$V$9=V9)*($W$6:$W$9>W9)) -> 0 | AB9: =SUMPRODUCT(($Q$6:$Q$9=Q9)*($X$6:$X$9=X9)*($V$6:$V$9=V9)*($W$6:$W$9=W9)*($AC$6:$AC$9<AC9)) -> 0 | AC9: 4 | AE9: 4 | AF9: =VLOOKUP($AE9,$O$6:$X$9,2,FALSE) -> República Tcheca | AG9: =VLOOKUP($AE9,$O$6:$X$9,3,FALSE) -> 1 | AH9: =VLOOKUP($AE9,$O$6:$X$9,4,FALSE) -> 3 | AI9: =VLOOKUP($AE9,$O$6:$X$9,5,FALSE) -> 0 | AJ9: =VLOOKUP($AE9,$O$6:$X$9,6,FALSE) -> 1 | AK9: =VLOOKUP($AE9,$O$6:$X$9,7,FALSE) -> 2 | AL9: =VLOOKUP($AE9,$O$6:$X$9,8,FALSE) -> 2 | AM9: =VLOOKUP($AE9,$O$6:$X$9,9,FALSE) -> 6 | AN9: =VLOOKUP($AE9,$O$6:$X$9,10,FALSE) -> -4 | AP9: =RANK(AR9,$AR$6:$AR$17)+SUM(BB9:BE9) -> 7 | AQ9: =AF26 -> Paraguai | AR9: =(AT9*3)+(AU9*1) -> 4 | AS9: =SUM(AT9:AV9) -> 3 | AT9: =VLOOKUP(AQ9,$P$5:$X$75,4,FALSE) -> 1 | AU9: =VLOOKUP(AQ9,$P$5:$X$75,5,FALSE) -> 1 | AV9: =VLOOKUP(AQ9,$P$5:$X$75,6,FALSE) -> 1 | AW9: =VLOOKUP(AQ9,$P$5:$X$75,7,FALSE) -> 2 | AX9: =VLOOKUP(AQ9,$P$5:$X$75,8,FALSE) -> 4 | AY9: =AW9-AX9 -> -2 | AZ9: D | BA9: =AQ9 -> Paraguai | BB9: =SUMPRODUCT(($AR$6:$AR$17=AR9)*($AY$6:$AY$17>AY9)) -> 5 | BC9: =SUMPRODUCT(($AR$6:$AR$17=AR9)*($AY$6:$AY$17=AY9)*($AW$6:$AW$17>AW9)) -> 1 | BD9: =SUMPRODUCT(($AR$6:$AR$17=AR9)*($AY$6:$AY$17=AY9)*($AW$6:$AW$17=AW9)*($AX$6:$AX$17>AX9)) -> 0 | BE9: =SUMPRODUCT(($AR$6:$AR$17=AR9)*($AY$6:$AY$17=AY9)*($AW$6:$AW$17=AW9)*($AX$6:$AX$17=AX9)*($BF$6:$BF$17<BF9)) -> 0 | BF9: 4 | BI9: 4 | BJ9: =VLOOKUP($BI9,$AP$6:$AY$17,2,FALSE) -> Gana | BK9: =VLOOKUP($BI9,$AP$6:$AY$17,3,FALSE) -> 4 | BL9: =VLOOKUP($BI9,$AP$6:$AY$17,4,FALSE) -> 3 | BM9: =VLOOKUP($BI9,$AP$6:$AY$17,5,FALSE) -> 1 | BN9: =VLOOKUP($BI9,$AP$6:$AY$17,6,FALSE) -> 1 | BO9: =VLOOKUP($BI9,$AP$6:$AY$17,7,FALSE) -> 1 | BP9: =VLOOKUP($BI9,$AP$6:$AY$17,8,FALSE) -> 2 | BQ9: =VLOOKUP($BI9,$AP$6:$AY$17,9,FALSE) -> 2 | BR9: =VLOOKUP($BI9,$AP$6:$AY$17,10,FALSE) -> 0
B10: B | C10: 46185 | D10: 15.00 | E10: =P12 -> Canadá | F10: 1 | G10: x | H10: 1 | I10: =P13 -> Bósnia | J10: =IF(F10=H10,"empate",IF(F10>H10,E10,I10)) -> empate | K10: =IF(F10="","",IF(H10="","",IF(J10="empate",E10,""))) -> Canadá | L10: =IF(E10="","",IF(F10="","",IF(M10="empate",I10,""))) -> Bósnia | M10: =IF(F10=H10,"empate",IF(F10<H10,E10,I10)) -> empate | P10: Grupo B | AE10: Grupo B | AP10: =RANK(AR10,$AR$6:$AR$17)+SUM(BB10:BE10) -> 3 | AQ10: =AF32 -> Equador | AR10: =(AT10*3)+(AU10*1) -> 4 | AS10: =SUM(AT10:AV10) -> 3 | AT10: =VLOOKUP(AQ10,$P$5:$X$75,4,FALSE) -> 1 | AU10: =VLOOKUP(AQ10,$P$5:$X$75,5,FALSE) -> 1 | AV10: =VLOOKUP(AQ10,$P$5:$X$75,6,FALSE) -> 1 | AW10: =VLOOKUP(AQ10,$P$5:$X$75,7,FALSE) -> 2 | AX10: =VLOOKUP(AQ10,$P$5:$X$75,8,FALSE) -> 2 | AY10: =AW10-AX10 -> 0 | AZ10: E | BA10: =AQ10 -> Equador | BB10: =SUMPRODUCT(($AR$6:$AR$17=AR10)*($AY$6:$AY$17>AY10)) -> 1 | BC10: =SUMPRODUCT(($AR$6:$AR$17=AR10)*($AY$6:$AY$17=AY10)*($AW$6:$AW$17>AW10)) -> 1 | BD10: =SUMPRODUCT(($AR$6:$AR$17=AR10)*($AY$6:$AY$17=AY10)*($AW$6:$AW$17=AW10)*($AX$6:$AX$17>AX10)) -> 0 | BE10: =SUMPRODUCT(($AR$6:$AR$17=AR10)*($AY$6:$AY$17=AY10)*($AW$6:$AW$17=AW10)*($AX$6:$AX$17=AX10)*($BF$6:$BF$17<BF10)) -> 0 | BF10: 5 | BI10: 5 | BJ10: =VLOOKUP($BI10,$AP$6:$AY$17,2,FALSE) -> Bósnia | BK10: =VLOOKUP($BI10,$AP$6:$AY$17,3,FALSE) -> 4 | BL10: =VLOOKUP($BI10,$AP$6:$AY$17,4,FALSE) -> 3 | BM10: =VLOOKUP($BI10,$AP$6:$AY$17,5,FALSE) -> 1 | BN10: =VLOOKUP($BI10,$AP$6:$AY$17,6,FALSE) -> 1 | BO10: =VLOOKUP($BI10,$AP$6:$AY$17,7,FALSE) -> 1 | BP10: =VLOOKUP($BI10,$AP$6:$AY$17,8,FALSE) -> 5 | BQ10: =VLOOKUP($BI10,$AP$6:$AY$17,9,FALSE) -> 6 | BR10: =VLOOKUP($BI10,$AP$6:$AY$17,10,FALSE) -> -1
B11: B | C11: 46186 | D11: 12.00 | E11: =P14 -> Qatar | F11: 1 | G11: x | H11: 1 | I11: =P15 -> Suiça | J11: =IF(F11=H11,"empate",IF(F11>H11,E11,I11)) -> empate | K11: =IF(F11="","",IF(H11="","",IF(J11="empate",E11,""))) -> Qatar | L11: =IF(E11="","",IF(F11="","",IF(M11="empate",I11,""))) -> Suiça | M11: =IF(F11=H11,"empate",IF(F11<H11,E11,I11)) -> empate | O11: Rk | P11: Sorteio | Q11: Pontos | R11: Jogos | S11: Vit | T11: Emp | U11: Der | V11: GP | W11: GC | X11: SG | Y11: SAL | Z11: PRO | AA11: CON | AB11: NM | AC11: Or. | AE11: P. | AF11: Seleção | AG11: P | AH11: J | AI11: V | AJ11: E | AK11: D | AL11: GP | AM11: GC | AN11: SG | AP11: =RANK(AR11,$AR$6:$AR$17)+SUM(BB11:BE11) -> 2 | AQ11: =AF38 -> Suécia | AR11: =(AT11*3)+(AU11*1) -> 4 | AS11: =SUM(AT11:AV11) -> 3 | AT11: =VLOOKUP(AQ11,$P$5:$X$75,4,FALSE) -> 1 | AU11: =VLOOKUP(AQ11,$P$5:$X$75,5,FALSE) -> 1 | AV11: =VLOOKUP(AQ11,$P$5:$X$75,6,FALSE) -> 1 | AW11: =VLOOKUP(AQ11,$P$5:$X$75,7,FALSE) -> 7 | AX11: =VLOOKUP(AQ11,$P$5:$X$75,8,FALSE) -> 7 | AY11: =AW11-AX11 -> 0 | AZ11: F | BA11: =AQ11 -> Suécia | BB11: =SUMPRODUCT(($AR$6:$AR$17=AR11)*($AY$6:$AY$17>AY11)) -> 1 | BC11: =SUMPRODUCT(($AR$6:$AR$17=AR11)*($AY$6:$AY$17=AY11)*($AW$6:$AW$17>AW11)) -> 0 | BD11: =SUMPRODUCT(($AR$6:$AR$17=AR11)*($AY$6:$AY$17=AY11)*($AW$6:$AW$17=AW11)*($AX$6:$AX$17>AX11)) -> 0 | BE11: =SUMPRODUCT(($AR$6:$AR$17=AR11)*($AY$6:$AY$17=AY11)*($AW$6:$AW$17=AW11)*($AX$6:$AX$17=AX11)*($BF$6:$BF$17<BF11)) -> 0 | BF11: 6 | BI11: 6 | BJ11: =VLOOKUP($BI11,$AP$6:$AY$17,2,FALSE) -> Argélia | BK11: =VLOOKUP($BI11,$AP$6:$AY$17,3,FALSE) -> 4 | BL11: =VLOOKUP($BI11,$AP$6:$AY$17,4,FALSE) -> 3 | BM11: =VLOOKUP($BI11,$AP$6:$AY$17,5,FALSE) -> 1 | BN11: =VLOOKUP($BI11,$AP$6:$AY$17,6,FALSE) -> 1 | BO11: =VLOOKUP($BI11,$AP$6:$AY$17,7,FALSE) -> 1 | BP11: =VLOOKUP($BI11,$AP$6:$AY$17,8,FALSE) -> 5 | BQ11: =VLOOKUP($BI11,$AP$6:$AY$17,9,FALSE) -> 7 | BR11: =VLOOKUP($BI11,$AP$6:$AY$17,10,FALSE) -> -2
B12: B | C12: 46191 | D12: 09.00 | E12: =P12 -> Canadá | F12: 6 | G12: x | H12: 0 | I12: =P14 -> Qatar | J12: =IF(F12=H12,"empate",IF(F12>H12,E12,I12)) -> Canadá | K12: =IF(F12="","",IF(H12="","",IF(J12="empate",E12,""))) | L12: =IF(E12="","",IF(F12="","",IF(M12="empate",I12,""))) | M12: =IF(F12=H12,"empate",IF(F12<H12,E12,I12)) -> Qatar | O12: =RANK(Q12,$Q$12:$Q$15)+SUM(Y12:AB12) -> 2 | P12: =Sorteios!F6 -> Canadá | Q12: =(S12*3)+(T12*1) -> 4 | R12: =SUM(S12:U12) -> 3 | S12: =COUNTIF(J:J,P12) -> 1 | T12: =COUNTIF(K:K,P12)+COUNTIF(L:L,P12) -> 1 | U12: =COUNTIF(M:M,P12) -> 1 | V12: =SUMIF(E:E,P12,F:F)+SUMIF(I:I,P12,H:H) -> 8 | W12: =SUMIF(E:E,P12,H:H)+SUMIF(I:I,P12,F:F) -> 3 | X12: =V12-W12 -> 5 | Y12: =SUMPRODUCT(($Q$12:$Q$15=Q12)*($X$12:$X$15>X12)) -> 0 | Z12: =SUMPRODUCT(($Q$12:$Q$15=Q12)*($X$12:$X$15=X12)*($V$12:$V$15>V12)) -> 0 | AA12: =SUMPRODUCT(($Q$12:$Q$15=Q12)*($X$12:$X$15=X12)*($V$12:$V$15=V12)*($W$12:$W$15>W12)) -> 0 | AB12: =SUMPRODUCT(($Q$12:$Q$15=Q12)*($X$12:$X$15=X12)*($V$12:$V$15=V12)*($W$12:$W$15=W12)*($AC$12:$AC$15<AC12)) -> 0 | AC12: 1 | AE12: 1 | AF12: =VLOOKUP($AE12,$O$12:$X$15,2,FALSE) -> Suiça | AG12: =VLOOKUP($AE12,$O$12:$X$15,3,FALSE) -> 7 | AH12: =VLOOKUP($AE12,$O$12:$X$15,4,FALSE) -> 3 | AI12: =VLOOKUP($AE12,$O$12:$X$15,5,FALSE) -> 2 | AJ12: =VLOOKUP($AE12,$O$12:$X$15,6,FALSE) -> 1 | AK12: =VLOOKUP($AE12,$O$12:$X$15,7,FALSE) -> 0 | AL12: =VLOOKUP($AE12,$O$12:$X$15,8,FALSE) -> 7 | AM12: =VLOOKUP($AE12,$O$12:$X$15,9,FALSE) -> 3 | AN12: =VLOOKUP($AE12,$O$12:$X$15,10,FALSE) -> 4 | AP12: =RANK(AR12,$AR$6:$AR$17)+SUM(BB12:BE12) -> 9 | AQ12: =AF44 -> Irã | AR12: =(AT12*3)+(AU12*1) -> 3 | AS12: =SUM(AT12:AV12) -> 3 | AT12: =VLOOKUP(AQ12,$P$5:$X$75,4,FALSE) -> 0 | AU12: =VLOOKUP(AQ12,$P$5:$X$75,5,FALSE) -> 3 | AV12: =VLOOKUP(AQ12,$P$5:$X$75,6,FALSE) -> 0 | AW12: =VLOOKUP(AQ12,$P$5:$X$75,7,FALSE) -> 3 | AX12: =VLOOKUP(AQ12,$P$5:$X$75,8,FALSE) -> 3 | AY12: =AW12-AX12 -> 0 | AZ12: G | BA12: =AQ12 -> Irã | BB12: =SUMPRODUCT(($AR$6:$AR$17=AR12)*($AY$6:$AY$17>AY12)) -> 1 | BC12: =SUMPRODUCT(($AR$6:$AR$17=AR12)*($AY$6:$AY$17=AY12)*($AW$6:$AW$17>AW12)) -> 0 | BD12: =SUMPRODUCT(($AR$6:$AR$17=AR12)*($AY$6:$AY$17=AY12)*($AW$6:$AW$17=AW12)*($AX$6:$AX$17>AX12)) -> 0 | BE12: =SUMPRODUCT(($AR$6:$AR$17=AR12)*($AY$6:$AY$17=AY12)*($AW$6:$AW$17=AW12)*($AX$6:$AX$17=AX12)*($BF$6:$BF$17<BF12)) -> 0 | BF12: 7 | BI12: 7 | BJ12: =VLOOKUP($BI12,$AP$6:$AY$17,2,FALSE) -> Paraguai | BK12: =VLOOKUP($BI12,$AP$6:$AY$17,3,FALSE) -> 4 | BL12: =VLOOKUP($BI12,$AP$6:$AY$17,4,FALSE) -> 3 | BM12: =VLOOKUP($BI12,$AP$6:$AY$17,5,FALSE) -> 1 | BN12: =VLOOKUP($BI12,$AP$6:$AY$17,6,FALSE) -> 1 | BO12: =VLOOKUP($BI12,$AP$6:$AY$17,7,FALSE) -> 1 | BP12: =VLOOKUP($BI12,$AP$6:$AY$17,8,FALSE) -> 2 | BQ12: =VLOOKUP($BI12,$AP$6:$AY$17,9,FALSE) -> 4 | BR12: =VLOOKUP($BI12,$AP$6:$AY$17,10,FALSE) -> -2
B13: B | C13: 46191 | D13: 15.00 | E13: =P15 -> Suiça | F13: 4 | G13: x | H13: 1 | I13: =P13 -> Bósnia | J13: =IF(F13=H13,"empate",IF(F13>H13,E13,I13)) -> Suiça | K13: =IF(F13="","",IF(H13="","",IF(J13="empate",E13,""))) | L13: =IF(E13="","",IF(F13="","",IF(M13="empate",I13,""))) | M13: =IF(F13=H13,"empate",IF(F13<H13,E13,I13)) -> Bósnia | O13: =RANK(Q13,$Q$12:$Q$15)+SUM(Y13:AB13) -> 3 | P13: =Sorteios!F7 -> Bósnia | Q13: =(S13*3)+(T13*1) -> 4 | R13: =SUM(S13:U13) -> 3 | S13: =COUNTIF(J:J,P13) -> 1 | T13: =COUNTIF(K:K,P13)+COUNTIF(L:L,P13) -> 1 | U13: =COUNTIF(M:M,P13) -> 1 | V13: =SUMIF(E:E,P13,F:F)+SUMIF(I:I,P13,H:H) -> 5 | W13: =SUMIF(E:E,P13,H:H)+SUMIF(I:I,P13,F:F) -> 6 | X13: =V13-W13 -> -1 | Y13: =SUMPRODUCT(($Q$12:$Q$15=Q13)*($X$12:$X$15>X13)) -> 1 | Z13: =SUMPRODUCT(($Q$12:$Q$15=Q13)*($X$12:$X$15=X13)*($V$12:$V$15>V13)) -> 0 | AA13: =SUMPRODUCT(($Q$12:$Q$15=Q13)*($X$12:$X$15=X13)*($V$12:$V$15=V13)*($W$12:$W$15>W13)) -> 0 | AB13: =SUMPRODUCT(($Q$12:$Q$15=Q13)*($X$12:$X$15=X13)*($V$12:$V$15=V13)*($W$12:$W$15=W13)*($AC$12:$AC$15<AC13)) -> 0 | AC13: 2 | AE13: 2 | AF13: =VLOOKUP($AE13,$O$12:$X$15,2,FALSE) -> Canadá | AG13: =VLOOKUP($AE13,$O$12:$X$15,3,FALSE) -> 4 | AH13: =VLOOKUP($AE13,$O$12:$X$15,4,FALSE) -> 3 | AI13: =VLOOKUP($AE13,$O$12:$X$15,5,FALSE) -> 1 | AJ13: =VLOOKUP($AE13,$O$12:$X$15,6,FALSE) -> 1 | AK13: =VLOOKUP($AE13,$O$12:$X$15,7,FALSE) -> 1 | AL13: =VLOOKUP($AE13,$O$12:$X$15,8,FALSE) -> 8 | AM13: =VLOOKUP($AE13,$O$12:$X$15,9,FALSE) -> 3 | AN13: =VLOOKUP($AE13,$O$12:$X$15,10,FALSE) -> 5 | AP13: =RANK(AR13,$AR$6:$AR$17)+SUM(BB13:BE13) -> 12 | AQ13: =AF50 -> Uruguai | AR13: =(AT13*3)+(AU13*1) -> 2 | AS13: =SUM(AT13:AV13) -> 3 | AT13: =VLOOKUP(AQ13,$P$5:$X$75,4,FALSE) -> 0 | AU13: =VLOOKUP(AQ13,$P$5:$X$75,5,FALSE) -> 2 | AV13: =VLOOKUP(AQ13,$P$5:$X$75,6,FALSE) -> 1 | AW13: =VLOOKUP(AQ13,$P$5:$X$75,7,FALSE) -> 3 | AX13: =VLOOKUP(AQ13,$P$5:$X$75,8,FALSE) -> 4 | AY13: =AW13-AX13 -> -1 | AZ13: H | BA13: =AQ13 -> Uruguai | BB13: =SUMPRODUCT(($AR$6:$AR$17=AR13)*($AY$6:$AY$17>AY13)) -> 0 | BC13: =SUMPRODUCT(($AR$6:$AR$17=AR13)*($AY$6:$AY$17=AY13)*($AW$6:$AW$17>AW13)) -> 0 | BD13: =SUMPRODUCT(($AR$6:$AR$17=AR13)*($AY$6:$AY$17=AY13)*($AW$6:$AW$17=AW13)*($AX$6:$AX$17>AX13)) -> 0 | BE13: =SUMPRODUCT(($AR$6:$AR$17=AR13)*($AY$6:$AY$17=AY13)*($AW$6:$AW$17=AW13)*($AX$6:$AX$17=AX13)*($BF$6:$BF$17<BF13)) -> 0 | BF13: 8 | BI13: 8 | BJ13: =VLOOKUP($BI13,$AP$6:$AY$17,2,FALSE) -> Senegal | BK13: =VLOOKUP($BI13,$AP$6:$AY$17,3,FALSE) -> 3 | BL13: =VLOOKUP($BI13,$AP$6:$AY$17,4,FALSE) -> 3 | BM13: =VLOOKUP($BI13,$AP$6:$AY$17,5,FALSE) -> 1 | BN13: =VLOOKUP($BI13,$AP$6:$AY$17,6,FALSE) -> 0 | BO13: =VLOOKUP($BI13,$AP$6:$AY$17,7,FALSE) -> 2 | BP13: =VLOOKUP($BI13,$AP$6:$AY$17,8,FALSE) -> 8 | BQ13: =VLOOKUP($BI13,$AP$6:$AY$17,9,FALSE) -> 6 | BR13: =VLOOKUP($BI13,$AP$6:$AY$17,10,FALSE) -> 2
B14: B | C14: 46197 | D14: 15.00 | E14: =P15 -> Suiça | F14: 2 | G14: x | H14: 1 | I14: =P12 -> Canadá | J14: =IF(F14=H14,"empate",IF(F14>H14,E14,I14)) -> Suiça | K14: =IF(F14="","",IF(H14="","",IF(J14="empate",E14,""))) | L14: =IF(E14="","",IF(F14="","",IF(M14="empate",I14,""))) | M14: =IF(F14=H14,"empate",IF(F14<H14,E14,I14)) -> Canadá | O14: =RANK(Q14,$Q$12:$Q$15)+SUM(Y14:AB14) -> 4 | P14: =Sorteios!F8 -> Qatar | Q14: =(S14*3)+(T14*1) -> 1 | R14: =SUM(S14:U14) -> 3 | S14: =COUNTIF(J:J,P14) -> 0 | T14: =COUNTIF(K:K,P14)+COUNTIF(L:L,P14) -> 1 | U14: =COUNTIF(M:M,P14) -> 2 | V14: =SUMIF(E:E,P14,F:F)+SUMIF(I:I,P14,H:H) -> 2 | W14: =SUMIF(E:E,P14,H:H)+SUMIF(I:I,P14,F:F) -> 10 | X14: =V14-W14 -> -8 | Y14: =SUMPRODUCT(($Q$12:$Q$15=Q14)*($X$12:$X$15>X14)) -> 0 | Z14: =SUMPRODUCT(($Q$12:$Q$15=Q14)*($X$12:$X$15=X14)*($V$12:$V$15>V14)) -> 0 | AA14: =SUMPRODUCT(($Q$12:$Q$15=Q14)*($X$12:$X$15=X14)*($V$12:$V$15=V14)*($W$12:$W$15>W14)) -> 0 | AB14: =SUMPRODUCT(($Q$12:$Q$15=Q14)*($X$12:$X$15=X14)*($V$12:$V$15=V14)*($W$12:$W$15=W14)*($AC$12:$AC$15<AC14)) -> 0 | AC14: 3 | AE14: 3 | AF14: =VLOOKUP($AE14,$O$12:$X$15,2,FALSE) -> Bósnia | AG14: =VLOOKUP($AE14,$O$12:$X$15,3,FALSE) -> 4 | AH14: =VLOOKUP($AE14,$O$12:$X$15,4,FALSE) -> 3 | AI14: =VLOOKUP($AE14,$O$12:$X$15,5,FALSE) -> 1 | AJ14: =VLOOKUP($AE14,$O$12:$X$15,6,FALSE) -> 1 | AK14: =VLOOKUP($AE14,$O$12:$X$15,7,FALSE) -> 1 | AL14: =VLOOKUP($AE14,$O$12:$X$15,8,FALSE) -> 5 | AM14: =VLOOKUP($AE14,$O$12:$X$15,9,FALSE) -> 6 | AN14: =VLOOKUP($AE14,$O$12:$X$15,10,FALSE) -> -1 | AP14: =RANK(AR14,$AR$6:$AR$17)+SUM(BB14:BE14) -> 8 | AQ14: =AF56 -> Senegal | AR14: =(AT14*3)+(AU14*1) -> 3 | AS14: =SUM(AT14:AV14) -> 3 | AT14: =VLOOKUP(AQ14,$P$5:$X$75,4,FALSE) -> 1 | AU14: =VLOOKUP(AQ14,$P$5:$X$75,5,FALSE) -> 0 | AV14: =VLOOKUP(AQ14,$P$5:$X$75,6,FALSE) -> 2 | AW14: =VLOOKUP(AQ14,$P$5:$X$75,7,FALSE) -> 8 | AX14: =VLOOKUP(AQ14,$P$5:$X$75,8,FALSE) -> 6 | AY14: =AW14-AX14 -> 2 | AZ14: I | BA14: =AQ14 -> Senegal | BB14: =SUMPRODUCT(($AR$6:$AR$17=AR14)*($AY$6:$AY$17>AY14)) -> 0 | BC14: =SUMPRODUCT(($AR$6:$AR$17=AR14)*($AY$6:$AY$17=AY14)*($AW$6:$AW$17>AW14)) -> 0 | BD14: =SUMPRODUCT(($AR$6:$AR$17=AR14)*($AY$6:$AY$17=AY14)*($AW$6:$AW$17=AW14)*($AX$6:$AX$17>AX14)) -> 0 | BE14: =SUMPRODUCT(($AR$6:$AR$17=AR14)*($AY$6:$AY$17=AY14)*($AW$6:$AW$17=AW14)*($AX$6:$AX$17=AX14)*($BF$6:$BF$17<BF14)) -> 0 | BF14: 9 | BI14: 9 | BJ14: =VLOOKUP($BI14,$AP$6:$AY$17,2,FALSE) -> Irã | BK14: =VLOOKUP($BI14,$AP$6:$AY$17,3,FALSE) -> 3 | BL14: =VLOOKUP($BI14,$AP$6:$AY$17,4,FALSE) -> 3 | BM14: =VLOOKUP($BI14,$AP$6:$AY$17,5,FALSE) -> 0 | BN14: =VLOOKUP($BI14,$AP$6:$AY$17,6,FALSE) -> 3 | BO14: =VLOOKUP($BI14,$AP$6:$AY$17,7,FALSE) -> 0 | BP14: =VLOOKUP($BI14,$AP$6:$AY$17,8,FALSE) -> 3 | BQ14: =VLOOKUP($BI14,$AP$6:$AY$17,9,FALSE) -> 3 | BR14: =VLOOKUP($BI14,$AP$6:$AY$17,10,FALSE) -> 0
B15: B | C15: 46197 | D15: 15.00 | E15: =P13 -> Bósnia | F15: 3 | G15: x | H15: 1 | I15: =P14 -> Qatar | J15: =IF(F15=H15,"empate",IF(F15>H15,E15,I15)) -> Bósnia | K15: =IF(F15="","",IF(H15="","",IF(J15="empate",E15,""))) | L15: =IF(E15="","",IF(F15="","",IF(M15="empate",I15,""))) | M15: =IF(F15=H15,"empate",IF(F15<H15,E15,I15)) -> Qatar | O15: =RANK(Q15,$Q$12:$Q$15)+SUM(Y15:AB15) -> 1 | P15: =Sorteios!F9 -> Suiça | Q15: =(S15*3)+(T15*1) -> 7 | R15: =SUM(S15:U15) -> 3 | S15: =COUNTIF(J:J,P15) -> 2 | T15: =COUNTIF(K:K,P15)+COUNTIF(L:L,P15) -> 1 | U15: =COUNTIF(M:M,P15) -> 0 | V15: =SUMIF(E:E,P15,F:F)+SUMIF(I:I,P15,H:H) -> 7 | W15: =SUMIF(E:E,P15,H:H)+SUMIF(I:I,P15,F:F) -> 3 | X15: =V15-W15 -> 4 | Y15: =SUMPRODUCT(($Q$12:$Q$15=Q15)*($X$12:$X$15>X15)) -> 0 | Z15: =SUMPRODUCT(($Q$12:$Q$15=Q15)*($X$12:$X$15=X15)*($V$12:$V$15>V15)) -> 0 | AA15: =SUMPRODUCT(($Q$12:$Q$15=Q15)*($X$12:$X$15=X15)*($V$12:$V$15=V15)*($W$12:$W$15>W15)) -> 0 | AB15: =SUMPRODUCT(($Q$12:$Q$15=Q15)*($X$12:$X$15=X15)*($V$12:$V$15=V15)*($W$12:$W$15=W15)*($AC$12:$AC$15<AC15)) -> 0 | AC15: 4 | AE15: 4 | AF15: =VLOOKUP($AE15,$O$12:$X$15,2,FALSE) -> Qatar | AG15: =VLOOKUP($AE15,$O$12:$X$15,3,FALSE) -> 1 | AH15: =VLOOKUP($AE15,$O$12:$X$15,4,FALSE) -> 3 | AI15: =VLOOKUP($AE15,$O$12:$X$15,5,FALSE) -> 0 | AJ15: =VLOOKUP($AE15,$O$12:$X$15,6,FALSE) -> 1 | AK15: =VLOOKUP($AE15,$O$12:$X$15,7,FALSE) -> 2 | AL15: =VLOOKUP($AE15,$O$12:$X$15,8,FALSE) -> 2 | AM15: =VLOOKUP($AE15,$O$12:$X$15,9,FALSE) -> 10 | AN15: =VLOOKUP($AE15,$O$12:$X$15,10,FALSE) -> -8 | AP15: =RANK(AR15,$AR$6:$AR$17)+SUM(BB15:BE15) -> 6 | AQ15: =AF62 -> Argélia | AR15: =(AT15*3)+(AU15*1) -> 4 | AS15: =SUM(AT15:AV15) -> 3 | AT15: =VLOOKUP(AQ15,$P$5:$X$75,4,FALSE) -> 1 | AU15: =VLOOKUP(AQ15,$P$5:$X$75,5,FALSE) -> 1 | AV15: =VLOOKUP(AQ15,$P$5:$X$75,6,FALSE) -> 1 | AW15: =VLOOKUP(AQ15,$P$5:$X$75,7,FALSE) -> 5 | AX15: =VLOOKUP(AQ15,$P$5:$X$75,8,FALSE) -> 7 | AY15: =AW15-AX15 -> -2 | AZ15: J | BA15: =AQ15 -> Argélia | BB15: =SUMPRODUCT(($AR$6:$AR$17=AR15)*($AY$6:$AY$17>AY15)) -> 5 | BC15: =SUMPRODUCT(($AR$6:$AR$17=AR15)*($AY$6:$AY$17=AY15)*($AW$6:$AW$17>AW15)) -> 0 | BD15: =SUMPRODUCT(($AR$6:$AR$17=AR15)*($AY$6:$AY$17=AY15)*($AW$6:$AW$17=AW15)*($AX$6:$AX$17>AX15)) -> 0 | BE15: =SUMPRODUCT(($AR$6:$AR$17=AR15)*($AY$6:$AY$17=AY15)*($AW$6:$AW$17=AW15)*($AX$6:$AX$17=AX15)*($BF$6:$BF$17<BF15)) -> 0 | BF15: 10 | BI15: 10 | BJ15: =VLOOKUP($BI15,$AP$6:$AY$17,2,FALSE) -> Coreia do Sul | BK15: =VLOOKUP($BI15,$AP$6:$AY$17,3,FALSE) -> 3 | BL15: =VLOOKUP($BI15,$AP$6:$AY$17,4,FALSE) -> 3 | BM15: =VLOOKUP($BI15,$AP$6:$AY$17,5,FALSE) -> 1 | BN15: =VLOOKUP($BI15,$AP$6:$AY$17,6,FALSE) -> 0 | BO15: =VLOOKUP($BI15,$AP$6:$AY$17,7,FALSE) -> 2 | BP15: =VLOOKUP($BI15,$AP$6:$AY$17,8,FALSE) -> 2 | BQ15: =VLOOKUP($BI15,$AP$6:$AY$17,9,FALSE) -> 3 | BR15: =VLOOKUP($BI15,$AP$6:$AY$17,10,FALSE) -> -1
B16: C | C16: 46186 | D16: 07.00 | E16: =P18 -> Brasil | F16: 1 | G16: x | H16: 1 | I16: =P19 -> Marrocos | J16: =IF(F16=H16,"empate",IF(F16>H16,E16,I16)) -> empate | K16: =IF(F16="","",IF(H16="","",IF(J16="empate",E16,""))) -> Brasil | L16: =IF(E16="","",IF(F16="","",IF(M16="empate",I16,""))) -> Marrocos | M16: =IF(F16=H16,"empate",IF(F16<H16,E16,I16)) -> empate | P16: Grupo C | AE16: Grupo C | AP16: =RANK(AR16,$AR$6:$AR$17)+SUM(BB16:BE16) -> 1 | AQ16: =AF68 -> RD Congo | AR16: =(AT16*3)+(AU16*1) -> 4 | AS16: =SUM(AT16:AV16) -> 3 | AT16: =VLOOKUP(AQ16,$P$5:$X$75,4,FALSE) -> 1 | AU16: =VLOOKUP(AQ16,$P$5:$X$75,5,FALSE) -> 1 | AV16: =VLOOKUP(AQ16,$P$5:$X$75,6,FALSE) -> 1 | AW16: =VLOOKUP(AQ16,$P$5:$X$75,7,FALSE) -> 4 | AX16: =VLOOKUP(AQ16,$P$5:$X$75,8,FALSE) -> 3 | AY16: =AW16-AX16 -> 1 | AZ16: K | BA16: =AQ16 -> RD Congo | BB16: =SUMPRODUCT(($AR$6:$AR$17=AR16)*($AY$6:$AY$17>AY16)) -> 0 | BC16: =SUMPRODUCT(($AR$6:$AR$17=AR16)*($AY$6:$AY$17=AY16)*($AW$6:$AW$17>AW16)) -> 0 | BD16: =SUMPRODUCT(($AR$6:$AR$17=AR16)*($AY$6:$AY$17=AY16)*($AW$6:$AW$17=AW16)*($AX$6:$AX$17>AX16)) -> 0 | BE16: =SUMPRODUCT(($AR$6:$AR$17=AR16)*($AY$6:$AY$17=AY16)*($AW$6:$AW$17=AW16)*($AX$6:$AX$17=AX16)*($BF$6:$BF$17<BF16)) -> 0 | BF16: 11 | BI16: 11 | BJ16: =VLOOKUP($BI16,$AP$6:$AY$17,2,FALSE) -> Escócia | BK16: =VLOOKUP($BI16,$AP$6:$AY$17,3,FALSE) -> 3 | BL16: =VLOOKUP($BI16,$AP$6:$AY$17,4,FALSE) -> 3 | BM16: =VLOOKUP($BI16,$AP$6:$AY$17,5,FALSE) -> 1 | BN16: =VLOOKUP($BI16,$AP$6:$AY$17,6,FALSE) -> 0 | BO16: =VLOOKUP($BI16,$AP$6:$AY$17,7,FALSE) -> 2 | BP16: =VLOOKUP($BI16,$AP$6:$AY$17,8,FALSE) -> 1 | BQ16: =VLOOKUP($BI16,$AP$6:$AY$17,9,FALSE) -> 4 | BR16: =VLOOKUP($BI16,$AP$6:$AY$17,10,FALSE) -> -3
B17: C | C17: 46186 | D17: 13.00 | E17: =P20 -> Haiti | F17: 0 | G17: x | H17: 1 | I17: =P21 -> Escócia | J17: =IF(F17=H17,"empate",IF(F17>H17,E17,I17)) -> Escócia | K17: =IF(F17="","",IF(H17="","",IF(J17="empate",E17,""))) | L17: =IF(E17="","",IF(F17="","",IF(M17="empate",I17,""))) | M17: =IF(F17=H17,"empate",IF(F17<H17,E17,I17)) -> Haiti | O17: Rk | P17: Sorteio | Q17: Pontos | R17: Jogos | S17: Vit | T17: Emp | U17: Der | V17: GP | W17: GC | X17: SG | Y17: SAL | Z17: PRO | AA17: CON | AB17: NM | AC17: Or. | AE17: P. | AF17: Seleção | AG17: P | AH17: J | AI17: V | AJ17: E | AK17: D | AL17: GP | AM17: GC | AN17: SG | AP17: =RANK(AR17,$AR$6:$AR$17)+SUM(BB17:BE17) -> 4 | AQ17: =AF74 -> Gana | AR17: =(AT17*3)+(AU17*1) -> 4 | AS17: =SUM(AT17:AV17) -> 3 | AT17: =VLOOKUP(AQ17,$P$5:$X$75,4,FALSE) -> 1 | AU17: =VLOOKUP(AQ17,$P$5:$X$75,5,FALSE) -> 1 | AV17: =VLOOKUP(AQ17,$P$5:$X$75,6,FALSE) -> 1 | AW17: =VLOOKUP(AQ17,$P$5:$X$75,7,FALSE) -> 2 | AX17: =VLOOKUP(AQ17,$P$5:$X$75,8,FALSE) -> 2 | AY17: =AW17-AX17 -> 0 | AZ17: L | BA17: =AQ17 -> Gana | BB17: =SUMPRODUCT(($AR$6:$AR$17=AR17)*($AY$6:$AY$17>AY17)) -> 1 | BC17: =SUMPRODUCT(($AR$6:$AR$17=AR17)*($AY$6:$AY$17=AY17)*($AW$6:$AW$17>AW17)) -> 1 | BD17: =SUMPRODUCT(($AR$6:$AR$17=AR17)*($AY$6:$AY$17=AY17)*($AW$6:$AW$17=AW17)*($AX$6:$AX$17>AX17)) -> 0 | BE17: =SUMPRODUCT(($AR$6:$AR$17=AR17)*($AY$6:$AY$17=AY17)*($AW$6:$AW$17=AW17)*($AX$6:$AX$17=AX17)*($BF$6:$BF$17<BF17)) -> 1 | BF17: 12 | BI17: 12 | BJ17: =VLOOKUP($BI17,$AP$6:$AY$17,2,FALSE) -> Uruguai | BK17: =VLOOKUP($BI17,$AP$6:$AY$17,3,FALSE) -> 2 | BL17: =VLOOKUP($BI17,$AP$6:$AY$17,4,FALSE) -> 3 | BM17: =VLOOKUP($BI17,$AP$6:$AY$17,5,FALSE) -> 0 | BN17: =VLOOKUP($BI17,$AP$6:$AY$17,6,FALSE) -> 2 | BO17: =VLOOKUP($BI17,$AP$6:$AY$17,7,FALSE) -> 1 | BP17: =VLOOKUP($BI17,$AP$6:$AY$17,8,FALSE) -> 3 | BQ17: =VLOOKUP($BI17,$AP$6:$AY$17,9,FALSE) -> 4 | BR17: =VLOOKUP($BI17,$AP$6:$AY$17,10,FALSE) -> -1
B18: C | C18: 46192 | D18: 12.00 | E18: =P18 -> Brasil | F18: 3 | G18: x | H18: 0 | I18: =P20 -> Haiti | J18: =IF(F18=H18,"empate",IF(F18>H18,E18,I18)) -> Brasil | K18: =IF(F18="","",IF(H18="","",IF(J18="empate",E18,""))) | L18: =IF(E18="","",IF(F18="","",IF(M18="empate",I18,""))) | M18: =IF(F18=H18,"empate",IF(F18<H18,E18,I18)) -> Haiti | O18: =RANK(Q18,$Q$18:$Q$21)+SUM(Y18:AB18) -> 1 | P18: =Sorteios!I6 -> Brasil | Q18: =(S18*3)+(T18*1) -> 7 | R18: =SUM(S18:U18) -> 3 | S18: =COUNTIF(J:J,P18) -> 2 | T18: =COUNTIF(K:K,P18)+COUNTIF(L:L,P18) -> 1 | U18: =COUNTIF(M:M,P18) -> 0 | V18: =SUMIF(E:E,P18,F:F)+SUMIF(I:I,P18,H:H) -> 7 | W18: =SUMIF(E:E,P18,H:H)+SUMIF(I:I,P18,F:F) -> 1 | X18: =V18-W18 -> 6 | Y18: =SUMPRODUCT(($Q$18:$Q$21=Q18)*($X$18:$X$21>X18)) -> 0 | Z18: =SUMPRODUCT(($Q$18:$Q$21=Q18)*($X$18:$X$21=X18)*($V$18:$V$21>V18)) -> 0 | AA18: =SUMPRODUCT(($Q$18:$Q$21=Q18)*($X$18:$X$21=X18)*($V$18:$V$21=V18)*($W$18:$W$21>W18)) -> 0 | AB18: =SUMPRODUCT(($Q$18:$Q$21=Q18)*($X$18:$X$21=X18)*($V$18:$V$21=V18)*($W$18:$W$21=W18)*($AC$18:$AC$21<AC18)) -> 0 | AC18: 1 | AE18: 1 | AF18: =VLOOKUP($AE18,$O$18:$X$21,2,FALSE) -> Brasil | AG18: =VLOOKUP($AE18,$O$18:$X$21,3,FALSE) -> 7 | AH18: =VLOOKUP($AE18,$O$18:$X$21,4,FALSE) -> 3 | AI18: =VLOOKUP($AE18,$O$18:$X$21,5,FALSE) -> 2 | AJ18: =VLOOKUP($AE18,$O$18:$X$21,6,FALSE) -> 1 | AK18: =VLOOKUP($AE18,$O$18:$X$21,7,FALSE) -> 0 | AL18: =VLOOKUP($AE18,$O$18:$X$21,8,FALSE) -> 7 | AM18: =VLOOKUP($AE18,$O$18:$X$21,9,FALSE) -> 1 | AN18: =VLOOKUP($AE18,$O$18:$X$21,10,FALSE) -> 6 | BL18: =SUM(BL6:BL17) -> 36
B19: C | C19: 46192 | D19: 09.00 | E19: =P21 -> Escócia | F19: 0 | G19: x | H19: 1 | I19: =P19 -> Marrocos | J19: =IF(F19=H19,"empate",IF(F19>H19,E19,I19)) -> Marrocos | K19: =IF(F19="","",IF(H19="","",IF(J19="empate",E19,""))) | L19: =IF(E19="","",IF(F19="","",IF(M19="empate",I19,""))) | M19: =IF(F19=H19,"empate",IF(F19<H19,E19,I19)) -> Escócia | O19: =RANK(Q19,$Q$18:$Q$21)+SUM(Y19:AB19) -> 2 | P19: =Sorteios!I7 -> Marrocos | Q19: =(S19*3)+(T19*1) -> 7 | R19: =SUM(S19:U19) -> 3 | S19: =COUNTIF(J:J,P19) -> 2 | T19: =COUNTIF(K:K,P19)+COUNTIF(L:L,P19) -> 1 | U19: =COUNTIF(M:M,P19) -> 0 | V19: =SUMIF(E:E,P19,F:F)+SUMIF(I:I,P19,H:H) -> 6 | W19: =SUMIF(E:E,P19,H:H)+SUMIF(I:I,P19,F:F) -> 3 | X19: =V19-W19 -> 3 | Y19: =SUMPRODUCT(($Q$18:$Q$21=Q19)*($X$18:$X$21>X19)) -> 1 | Z19: =SUMPRODUCT(($Q$18:$Q$21=Q19)*($X$18:$X$21=X19)*($V$18:$V$21>V19)) -> 0 | AA19: =SUMPRODUCT(($Q$18:$Q$21=Q19)*($X$18:$X$21=X19)*($V$18:$V$21=V19)*($W$18:$W$21>W19)) -> 0 | AB19: =SUMPRODUCT(($Q$18:$Q$21=Q19)*($X$18:$X$21=X19)*($V$18:$V$21=V19)*($W$18:$W$21=W19)*($AC$18:$AC$21<AC19)) -> 0 | AC19: 2 | AE19: 2 | AF19: =VLOOKUP($AE19,$O$18:$X$21,2,FALSE) -> Marrocos | AG19: =VLOOKUP($AE19,$O$18:$X$21,3,FALSE) -> 7 | AH19: =VLOOKUP($AE19,$O$18:$X$21,4,FALSE) -> 3 | AI19: =VLOOKUP($AE19,$O$18:$X$21,5,FALSE) -> 2 | AJ19: =VLOOKUP($AE19,$O$18:$X$21,6,FALSE) -> 1 | AK19: =VLOOKUP($AE19,$O$18:$X$21,7,FALSE) -> 0 | AL19: =VLOOKUP($AE19,$O$18:$X$21,8,FALSE) -> 6 | AM19: =VLOOKUP($AE19,$O$18:$X$21,9,FALSE) -> 3 | AN19: =VLOOKUP($AE19,$O$18:$X$21,10,FALSE) -> 3
B20: C | C20: 46197 | D20: 11.00 | E20: =P21 -> Escócia | F20: 0 | G20: x | H20: 3 | I20: =P18 -> Brasil | J20: =IF(F20=H20,"empate",IF(F20>H20,E20,I20)) -> Brasil | K20: =IF(F20="","",IF(H20="","",IF(J20="empate",E20,""))) | L20: =IF(E20="","",IF(F20="","",IF(M20="empate",I20,""))) | M20: =IF(F20=H20,"empate",IF(F20<H20,E20,I20)) -> Escócia | O20: =RANK(Q20,$Q$18:$Q$21)+SUM(Y20:AB20) -> 4 | P20: =Sorteios!I8 -> Haiti | Q20: =(S20*3)+(T20*1) -> 0 | R20: =SUM(S20:U20) -> 3 | S20: =COUNTIF(J:J,P20) -> 0 | T20: =COUNTIF(K:K,P20)+COUNTIF(L:L,P20) -> 0 | U20: =COUNTIF(M:M,P20) -> 3 | V20: =SUMIF(E:E,P20,F:F)+SUMIF(I:I,P20,H:H) -> 2 | W20: =SUMIF(E:E,P20,H:H)+SUMIF(I:I,P20,F:F) -> 8 | X20: =V20-W20 -> -6 | Y20: =SUMPRODUCT(($Q$18:$Q$21=Q20)*($X$18:$X$21>X20)) -> 0 | Z20: =SUMPRODUCT(($Q$18:$Q$21=Q20)*($X$18:$X$21=X20)*($V$18:$V$21>V20)) -> 0 | AA20: =SUMPRODUCT(($Q$18:$Q$21=Q20)*($X$18:$X$21=X20)*($V$18:$V$21=V20)*($W$18:$W$21>W20)) -> 0 | AB20: =SUMPRODUCT(($Q$18:$Q$21=Q20)*($X$18:$X$21=X20)*($V$18:$V$21=V20)*($W$18:$W$21=W20)*($AC$18:$AC$21<AC20)) -> 0 | AC20: 3 | AE20: 3 | AF20: =VLOOKUP($AE20,$O$18:$X$21,2,FALSE) -> Escócia | AG20: =VLOOKUP($AE20,$O$18:$X$21,3,FALSE) -> 3 | AH20: =VLOOKUP($AE20,$O$18:$X$21,4,FALSE) -> 3 | AI20: =VLOOKUP($AE20,$O$18:$X$21,5,FALSE) -> 1 | AJ20: =VLOOKUP($AE20,$O$18:$X$21,6,FALSE) -> 0 | AK20: =VLOOKUP($AE20,$O$18:$X$21,7,FALSE) -> 2 | AL20: =VLOOKUP($AE20,$O$18:$X$21,8,FALSE) -> 1 | AM20: =VLOOKUP($AE20,$O$18:$X$21,9,FALSE) -> 4 | AN20: =VLOOKUP($AE20,$O$18:$X$21,10,FALSE) -> -3
B21: C | C21: 46197 | D21: 11.00 | E21: =P19 -> Marrocos | F21: 4 | G21: x | H21: 2 | I21: =P20 -> Haiti | J21: =IF(F21=H21,"empate",IF(F21>H21,E21,I21)) -> Marrocos | K21: =IF(F21="","",IF(H21="","",IF(J21="empate",E21,""))) | L21: =IF(E21="","",IF(F21="","",IF(M21="empate",I21,""))) | M21: =IF(F21=H21,"empate",IF(F21<H21,E21,I21)) -> Haiti | O21: =RANK(Q21,$Q$18:$Q$21)+SUM(Y21:AB21) -> 3 | P21: =Sorteios!I9 -> Escócia | Q21: =(S21*3)+(T21*1) -> 3 | R21: =SUM(S21:U21) -> 3 | S21: =COUNTIF(J:J,P21) -> 1 | T21: =COUNTIF(K:K,P21)+COUNTIF(L:L,P21) -> 0 | U21: =COUNTIF(M:M,P21) -> 2 | V21: =SUMIF(E:E,P21,F:F)+SUMIF(I:I,P21,H:H) -> 1 | W21: =SUMIF(E:E,P21,H:H)+SUMIF(I:I,P21,F:F) -> 4 | X21: =V21-W21 -> -3 | Y21: =SUMPRODUCT(($Q$18:$Q$21=Q21)*($X$18:$X$21>X21)) -> 0 | Z21: =SUMPRODUCT(($Q$18:$Q$21=Q21)*($X$18:$X$21=X21)*($V$18:$V$21>V21)) -> 0 | AA21: =SUMPRODUCT(($Q$18:$Q$21=Q21)*($X$18:$X$21=X21)*($V$18:$V$21=V21)*($W$18:$W$21>W21)) -> 0 | AB21: =SUMPRODUCT(($Q$18:$Q$21=Q21)*($X$18:$X$21=X21)*($V$18:$V$21=V21)*($W$18:$W$21=W21)*($AC$18:$AC$21<AC21)) -> 0 | AC21: 4 | AE21: 4 | AF21: =VLOOKUP($AE21,$O$18:$X$21,2,FALSE) -> Haiti | AG21: =VLOOKUP($AE21,$O$18:$X$21,3,FALSE) -> 0 | AH21: =VLOOKUP($AE21,$O$18:$X$21,4,FALSE) -> 3 | AI21: =VLOOKUP($AE21,$O$18:$X$21,5,FALSE) -> 0 | AJ21: =VLOOKUP($AE21,$O$18:$X$21,6,FALSE) -> 0 | AK21: =VLOOKUP($AE21,$O$18:$X$21,7,FALSE) -> 3 | AL21: =VLOOKUP($AE21,$O$18:$X$21,8,FALSE) -> 2 | AM21: =VLOOKUP($AE21,$O$18:$X$21,9,FALSE) -> 8 | AN21: =VLOOKUP($AE21,$O$18:$X$21,10,FALSE) -> -6 | AP21: 1 | AQ21: =VLOOKUP($BI6,$AP$6:$AZ$17,11,FALSE) -> K | AR21: =CODE(AQ21) -> 75
B22: D | C22: 46185 | D22: 10.00 | E22: =P24 -> Estados Unidos | F22: 4 | G22: x | H22: 1 | I22: =P25 -> Paraguai | J22: =IF(F22=H22,"empate",IF(F22>H22,E22,I22)) -> Estados Unidos | K22: =IF(F22="","",IF(H22="","",IF(J22="empate",E22,""))) | L22: =IF(E22="","",IF(F22="","",IF(M22="empate",I22,""))) | M22: =IF(F22=H22,"empate",IF(F22<H22,E22,I22)) -> Paraguai | P22: Grupo D | AE22: Grupo D | AP22: 2 | AQ22: =VLOOKUP($BI7,$AP$6:$AZ$17,11,FALSE) -> F | AR22: =CODE(AQ22) -> 70 | BJ22: Apoio
B23: D | C23: 46186 | D23: 16.00 | E23: =P26 -> Austrália | F23: 2 | G23: x | H23: 0 | I23: =P27 -> Turquia | J23: =IF(F23=H23,"empate",IF(F23>H23,E23,I23)) -> Austrália | K23: =IF(F23="","",IF(H23="","",IF(J23="empate",E23,""))) | L23: =IF(E23="","",IF(F23="","",IF(M23="empate",I23,""))) | M23: =IF(F23=H23,"empate",IF(F23<H23,E23,I23)) -> Turquia | O23: Rk | P23: Sorteio | Q23: Pontos | R23: Jogos | S23: Vit | T23: Emp | U23: Der | V23: GP | W23: GC | X23: SG | Y23: SAL | Z23: PRO | AA23: CON | AB23: NM | AC23: Or. | AE23: P. | AF23: Seleção | AG23: P | AH23: J | AI23: V | AJ23: E | AK23: D | AL23: GP | AM23: GC | AN23: SG | AP23: 3 | AQ23: =VLOOKUP($BI8,$AP$6:$AZ$17,11,FALSE) -> E | AR23: =CODE(AQ23) -> 69
B24: D | C24: 46192 | D24: 15.00 | E24: =P24 -> Estados Unidos | F24: 2 | G24: x | H24: 0 | I24: =P26 -> Austrália | J24: =IF(F24=H24,"empate",IF(F24>H24,E24,I24)) -> Estados Unidos | K24: =IF(F24="","",IF(H24="","",IF(J24="empate",E24,""))) | L24: =IF(E24="","",IF(F24="","",IF(M24="empate",I24,""))) | M24: =IF(F24=H24,"empate",IF(F24<H24,E24,I24)) -> Austrália | O24: =RANK(Q24,$Q$24:$Q$27)+SUM(Y24:AB24) -> 1 | P24: =Sorteios!C14 -> Estados Unidos | Q24: =(S24*3)+(T24*1) -> 6 | R24: =SUM(S24:U24) -> 3 | S24: =COUNTIF(J:J,P24) -> 2 | T24: =COUNTIF(K:K,P24)+COUNTIF(L:L,P24) -> 0 | U24: =COUNTIF(M:M,P24) -> 1 | V24: =SUMIF(E:E,P24,F:F)+SUMIF(I:I,P24,H:H) -> 8 | W24: =SUMIF(E:E,P24,H:H)+SUMIF(I:I,P24,F:F) -> 4 | X24: =V24-W24 -> 4 | Y24: =SUMPRODUCT(($Q$24:$Q$27=Q24)*($X$24:$X$27>X24)) -> 0 | Z24: =SUMPRODUCT(($Q$24:$Q$27=Q24)*($X$24:$X$27=X24)*($V$24:$V$27>V24)) -> 0 | AA24: =SUMPRODUCT(($Q$24:$Q$27=Q24)*($X$24:$X$27=X24)*($V$24:$V$27=V24)*($W$24:$W$27>W24)) -> 0 | AB24: =SUMPRODUCT(($Q$24:$Q$27=Q24)*($X$24:$X$27=X24)*($V$24:$V$27=V24)*($W$24:$W$27=W24)*($AC$24:$AC$27<AC24)) -> 0 | AC24: 1 | AE24: 1 | AF24: =VLOOKUP($AE24,$O$24:$X$27,2,FALSE) -> Estados Unidos | AG24: =VLOOKUP($AE24,$O$24:$X$27,3,FALSE) -> 6 | AH24: =VLOOKUP($AE24,$O$24:$X$27,4,FALSE) -> 3 | AI24: =VLOOKUP($AE24,$O$24:$X$27,5,FALSE) -> 2 | AJ24: =VLOOKUP($AE24,$O$24:$X$27,6,FALSE) -> 0 | AK24: =VLOOKUP($AE24,$O$24:$X$27,7,FALSE) -> 1 | AL24: =VLOOKUP($AE24,$O$24:$X$27,8,FALSE) -> 8 | AM24: =VLOOKUP($AE24,$O$24:$X$27,9,FALSE) -> 4 | AN24: =VLOOKUP($AE24,$O$24:$X$27,10,FALSE) -> 4 | AP24: 4 | AQ24: =VLOOKUP($BI9,$AP$6:$AZ$17,11,FALSE) -> L | AR24: =CODE(AQ24) -> 76
B25: D | C25: 46192 | D25: 12.00 | E25: =P27 -> Turquia | F25: 0 | G25: x | H25: 1 | I25: =P25 -> Paraguai | J25: =IF(F25=H25,"empate",IF(F25>H25,E25,I25)) -> Paraguai | K25: =IF(F25="","",IF(H25="","",IF(J25="empate",E25,""))) | L25: =IF(E25="","",IF(F25="","",IF(M25="empate",I25,""))) | M25: =IF(F25=H25,"empate",IF(F25<H25,E25,I25)) -> Turquia | O25: =RANK(Q25,$Q$24:$Q$27)+SUM(Y25:AB25) -> 3 | P25: =Sorteios!C15 -> Paraguai | Q25: =(S25*3)+(T25*1) -> 4 | R25: =SUM(S25:U25) -> 3 | S25: =COUNTIF(J:J,P25) -> 1 | T25: =COUNTIF(K:K,P25)+COUNTIF(L:L,P25) -> 1 | U25: =COUNTIF(M:M,P25) -> 1 | V25: =SUMIF(E:E,P25,F:F)+SUMIF(I:I,P25,H:H) -> 2 | W25: =SUMIF(E:E,P25,H:H)+SUMIF(I:I,P25,F:F) -> 4 | X25: =V25-W25 -> -2 | Y25: =SUMPRODUCT(($Q$24:$Q$27=Q25)*($X$24:$X$27>X25)) -> 1 | Z25: =SUMPRODUCT(($Q$24:$Q$27=Q25)*($X$24:$X$27=X25)*($V$24:$V$27>V25)) -> 0 | AA25: =SUMPRODUCT(($Q$24:$Q$27=Q25)*($X$24:$X$27=X25)*($V$24:$V$27=V25)*($W$24:$W$27>W25)) -> 0 | AB25: =SUMPRODUCT(($Q$24:$Q$27=Q25)*($X$24:$X$27=X25)*($V$24:$V$27=V25)*($W$24:$W$27=W25)*($AC$24:$AC$27<AC25)) -> 0 | AC25: 2 | AE25: 2 | AF25: =VLOOKUP($AE25,$O$24:$X$27,2,FALSE) -> Austrália | AG25: =VLOOKUP($AE25,$O$24:$X$27,3,FALSE) -> 4 | AH25: =VLOOKUP($AE25,$O$24:$X$27,4,FALSE) -> 3 | AI25: =VLOOKUP($AE25,$O$24:$X$27,5,FALSE) -> 1 | AJ25: =VLOOKUP($AE25,$O$24:$X$27,6,FALSE) -> 1 | AK25: =VLOOKUP($AE25,$O$24:$X$27,7,FALSE) -> 1 | AL25: =VLOOKUP($AE25,$O$24:$X$27,8,FALSE) -> 2 | AM25: =VLOOKUP($AE25,$O$24:$X$27,9,FALSE) -> 2 | AN25: =VLOOKUP($AE25,$O$24:$X$27,10,FALSE) -> 0 | AP25: 5 | AQ25: =VLOOKUP($BI10,$AP$6:$AZ$17,11,FALSE) -> B | AR25: =CODE(AQ25) -> 66
B26: D | C26: 46198 | D26: 15.00 | E26: =P27 -> Turquia | F26: 3 | G26: x | H26: 2 | I26: =P24 -> Estados Unidos | J26: =IF(F26=H26,"empate",IF(F26>H26,E26,I26)) -> Turquia | K26: =IF(F26="","",IF(H26="","",IF(J26="empate",E26,""))) | L26: =IF(E26="","",IF(F26="","",IF(M26="empate",I26,""))) | M26: =IF(F26=H26,"empate",IF(F26<H26,E26,I26)) -> Estados Unidos | O26: =RANK(Q26,$Q$24:$Q$27)+SUM(Y26:AB26) -> 2 | P26: =Sorteios!C16 -> Austrália | Q26: =(S26*3)+(T26*1) -> 4 | R26: =SUM(S26:U26) -> 3 | S26: =COUNTIF(J:J,P26) -> 1 | T26: =COUNTIF(K:K,P26)+COUNTIF(L:L,P26) -> 1 | U26: =COUNTIF(M:M,P26) -> 1 | V26: =SUMIF(E:E,P26,F:F)+SUMIF(I:I,P26,H:H) -> 2 | W26: =SUMIF(E:E,P26,H:H)+SUMIF(I:I,P26,F:F) -> 2 | X26: =V26-W26 -> 0 | Y26: =SUMPRODUCT(($Q$24:$Q$27=Q26)*($X$24:$X$27>X26)) -> 0 | Z26: =SUMPRODUCT(($Q$24:$Q$27=Q26)*($X$24:$X$27=X26)*($V$24:$V$27>V26)) -> 0 | AA26: =SUMPRODUCT(($Q$24:$Q$27=Q26)*($X$24:$X$27=X26)*($V$24:$V$27=V26)*($W$24:$W$27>W26)) -> 0 | AB26: =SUMPRODUCT(($Q$24:$Q$27=Q26)*($X$24:$X$27=X26)*($V$24:$V$27=V26)*($W$24:$W$27=W26)*($AC$24:$AC$27<AC26)) -> 0 | AC26: 3 | AE26: 3 | AF26: =VLOOKUP($AE26,$O$24:$X$27,2,FALSE) -> Paraguai | AG26: =VLOOKUP($AE26,$O$24:$X$27,3,FALSE) -> 4 | AH26: =VLOOKUP($AE26,$O$24:$X$27,4,FALSE) -> 3 | AI26: =VLOOKUP($AE26,$O$24:$X$27,5,FALSE) -> 1 | AJ26: =VLOOKUP($AE26,$O$24:$X$27,6,FALSE) -> 1 | AK26: =VLOOKUP($AE26,$O$24:$X$27,7,FALSE) -> 1 | AL26: =VLOOKUP($AE26,$O$24:$X$27,8,FALSE) -> 2 | AM26: =VLOOKUP($AE26,$O$24:$X$27,9,FALSE) -> 4 | AN26: =VLOOKUP($AE26,$O$24:$X$27,10,FALSE) -> -2 | AP26: 6 | AQ26: =VLOOKUP($BI11,$AP$6:$AZ$17,11,FALSE) -> J | AR26: =CODE(AQ26) -> 74
B27: D | C27: 46198 | D27: 15.00 | E27: =P25 -> Paraguai | F27: 0 | G27: x | H27: 0 | I27: =P26 -> Austrália | J27: =IF(F27=H27,"empate",IF(F27>H27,E27,I27)) -> empate | K27: =IF(F27="","",IF(H27="","",IF(J27="empate",E27,""))) -> Paraguai | L27: =IF(E27="","",IF(F27="","",IF(M27="empate",I27,""))) -> Austrália | M27: =IF(F27=H27,"empate",IF(F27<H27,E27,I27)) -> empate | O27: =RANK(Q27,$Q$24:$Q$27)+SUM(Y27:AB27) -> 4 | P27: =Sorteios!C17 -> Turquia | Q27: =(S27*3)+(T27*1) -> 3 | R27: =SUM(S27:U27) -> 3 | S27: =COUNTIF(J:J,P27) -> 1 | T27: =COUNTIF(K:K,P27)+COUNTIF(L:L,P27) -> 0 | U27: =COUNTIF(M:M,P27) -> 2 | V27: =SUMIF(E:E,P27,F:F)+SUMIF(I:I,P27,H:H) -> 3 | W27: =SUMIF(E:E,P27,H:H)+SUMIF(I:I,P27,F:F) -> 5 | X27: =V27-W27 -> -2 | Y27: =SUMPRODUCT(($Q$24:$Q$27=Q27)*($X$24:$X$27>X27)) -> 0 | Z27: =SUMPRODUCT(($Q$24:$Q$27=Q27)*($X$24:$X$27=X27)*($V$24:$V$27>V27)) -> 0 | AA27: =SUMPRODUCT(($Q$24:$Q$27=Q27)*($X$24:$X$27=X27)*($V$24:$V$27=V27)*($W$24:$W$27>W27)) -> 0 | AB27: =SUMPRODUCT(($Q$24:$Q$27=Q27)*($X$24:$X$27=X27)*($V$24:$V$27=V27)*($W$24:$W$27=W27)*($AC$24:$AC$27<AC27)) -> 0 | AC27: 4 | AE27: 4 | AF27: =VLOOKUP($AE27,$O$24:$X$27,2,FALSE) -> Turquia | AG27: =VLOOKUP($AE27,$O$24:$X$27,3,FALSE) -> 3 | AH27: =VLOOKUP($AE27,$O$24:$X$27,4,FALSE) -> 3 | AI27: =VLOOKUP($AE27,$O$24:$X$27,5,FALSE) -> 1 | AJ27: =VLOOKUP($AE27,$O$24:$X$27,6,FALSE) -> 0 | AK27: =VLOOKUP($AE27,$O$24:$X$27,7,FALSE) -> 2 | AL27: =VLOOKUP($AE27,$O$24:$X$27,8,FALSE) -> 3 | AM27: =VLOOKUP($AE27,$O$24:$X$27,9,FALSE) -> 5 | AN27: =VLOOKUP($AE27,$O$24:$X$27,10,FALSE) -> -2 | AP27: 7 | AQ27: =VLOOKUP($BI12,$AP$6:$AZ$17,11,FALSE) -> D | AR27: =CODE(AQ27) -> 68
B28: E | C28: 46187 | D28: 15.00 | E28: =P30 -> Alemanha | F28: 7 | G28: x | H28: 1 | I28: =P31 -> Curaçau | J28: =IF(F28=H28,"empate",IF(F28>H28,E28,I28)) -> Alemanha | K28: =IF(F28="","",IF(H28="","",IF(J28="empate",E28,""))) | L28: =IF(E28="","",IF(F28="","",IF(M28="empate",I28,""))) | M28: =IF(F28=H28,"empate",IF(F28<H28,E28,I28)) -> Curaçau | P28: Grupo E | AE28: Grupo E | AP28: 8 | AQ28: =VLOOKUP($BI13,$AP$6:$AZ$17,11,FALSE) -> I | AR28: =CODE(AQ28) -> 73
B29: E | C29: 46187 | D29: 09.00 | E29: =P32 -> Costa do Marfim | F29: 1 | G29: x | H29: 0 | I29: =P33 -> Equador | J29: =IF(F29=H29,"empate",IF(F29>H29,E29,I29)) -> Costa do Marfim | K29: =IF(F29="","",IF(H29="","",IF(J29="empate",E29,""))) | L29: =IF(E29="","",IF(F29="","",IF(M29="empate",I29,""))) | M29: =IF(F29=H29,"empate",IF(F29<H29,E29,I29)) -> Equador | O29: Rk | P29: Sorteio | Q29: Pontos | R29: Jogos | S29: Vit | T29: Emp | U29: Der | V29: GP | W29: GC | X29: SG | Y29: SAL | Z29: PRO | AA29: CON | AB29: NM | AC29: Or. | AE29: P. | AF29: Seleção | AG29: P | AH29: J | AI29: V | AJ29: E | AK29: D | AL29: GP | AM29: GC | AN29: SG
B30: E | C30: 46193 | D30: 09.00 | E30: =P30 -> Alemanha | F30: 2 | G30: x | H30: 1 | I30: =P32 -> Costa do Marfim | J30: =IF(F30=H30,"empate",IF(F30>H30,E30,I30)) -> Alemanha | K30: =IF(F30="","",IF(H30="","",IF(J30="empate",E30,""))) | L30: =IF(E30="","",IF(F30="","",IF(M30="empate",I30,""))) | M30: =IF(F30=H30,"empate",IF(F30<H30,E30,I30)) -> Costa do Marfim | O30: =RANK(Q30,$Q$30:$Q$33)+SUM(Y30:AB30) -> 1 | P30: =Sorteios!F14 -> Alemanha | Q30: =(S30*3)+(T30*1) -> 6 | R30: =SUM(S30:U30) -> 3 | S30: =COUNTIF(J:J,P30) -> 2 | T30: =COUNTIF(K:K,P30)+COUNTIF(L:L,P30) -> 0 | U30: =COUNTIF(M:M,P30) -> 1 | V30: =SUMIF(E:E,P30,F:F)+SUMIF(I:I,P30,H:H) -> 10 | W30: =SUMIF(E:E,P30,H:H)+SUMIF(I:I,P30,F:F) -> 4 | X30: =V30-W30 -> 6 | Y30: =SUMPRODUCT(($Q$30:$Q$33=Q30)*($X$30:$X$33>X30)) -> 0 | Z30: =SUMPRODUCT(($Q$30:$Q$33=Q30)*($X$30:$X$33=X30)*($V$30:$V$33>V30)) -> 0 | AA30: =SUMPRODUCT(($Q$30:$Q$33=Q30)*($X$30:$X$33=X30)*($V$30:$V$33=V30)*($W$30:$W$33>W30)) -> 0 | AB30: =SUMPRODUCT(($Q$30:$Q$33=Q30)*($X$30:$X$33=X30)*($V$30:$V$33=V30)*($W$30:$W$33=W30)*($AC$30:$AC$33<AC30)) -> 0 | AC30: 1 | AE30: 1 | AF30: =VLOOKUP($AE30,$O$30:$X$33,2,FALSE) -> Alemanha | AG30: =VLOOKUP($AE30,$O$30:$X$33,3,FALSE) -> 6 | AH30: =VLOOKUP($AE30,$O$30:$X$33,4,FALSE) -> 3 | AI30: =VLOOKUP($AE30,$O$30:$X$33,5,FALSE) -> 2 | AJ30: =VLOOKUP($AE30,$O$30:$X$33,6,FALSE) -> 0 | AK30: =VLOOKUP($AE30,$O$30:$X$33,7,FALSE) -> 1 | AL30: =VLOOKUP($AE30,$O$30:$X$33,8,FALSE) -> 10 | AM30: =VLOOKUP($AE30,$O$30:$X$33,9,FALSE) -> 4 | AN30: =VLOOKUP($AE30,$O$30:$X$33,10,FALSE) -> 6 | AQ30: =CHAR(SMALL($AR$21:$AR$28,1)) -> B | AR30: =_xlfn.CONCAT(3,AQ30) -> 3B | AS30: =VLOOKUP(AQ30,$AZ$6:$BA$17,2,FALSE) -> Bósnia
B31: E | C31: 46193 | D31: 15.00 | E31: =P33 -> Equador | F31: 0 | G31: x | H31: 0 | I31: =P31 -> Curaçau | J31: =IF(F31=H31,"empate",IF(F31>H31,E31,I31)) -> empate | K31: =IF(F31="","",IF(H31="","",IF(J31="empate",E31,""))) -> Equador | L31: =IF(E31="","",IF(F31="","",IF(M31="empate",I31,""))) -> Curaçau | M31: =IF(F31=H31,"empate",IF(F31<H31,E31,I31)) -> empate | O31: =RANK(Q31,$Q$30:$Q$33)+SUM(Y31:AB31) -> 4 | P31: =Sorteios!F15 -> Curaçau | Q31: =(S31*3)+(T31*1) -> 1 | R31: =SUM(S31:U31) -> 3 | S31: =COUNTIF(J:J,P31) -> 0 | T31: =COUNTIF(K:K,P31)+COUNTIF(L:L,P31) -> 1 | U31: =COUNTIF(M:M,P31) -> 2 | V31: =SUMIF(E:E,P31,F:F)+SUMIF(I:I,P31,H:H) -> 1 | W31: =SUMIF(E:E,P31,H:H)+SUMIF(I:I,P31,F:F) -> 9 | X31: =V31-W31 -> -8 | Y31: =SUMPRODUCT(($Q$30:$Q$33=Q31)*($X$30:$X$33>X31)) -> 0 | Z31: =SUMPRODUCT(($Q$30:$Q$33=Q31)*($X$30:$X$33=X31)*($V$30:$V$33>V31)) -> 0 | AA31: =SUMPRODUCT(($Q$30:$Q$33=Q31)*($X$30:$X$33=X31)*($V$30:$V$33=V31)*($W$30:$W$33>W31)) -> 0 | AB31: =SUMPRODUCT(($Q$30:$Q$33=Q31)*($X$30:$X$33=X31)*($V$30:$V$33=V31)*($W$30:$W$33=W31)*($AC$30:$AC$33<AC31)) -> 0 | AC31: 2 | AE31: 2 | AF31: =VLOOKUP($AE31,$O$30:$X$33,2,FALSE) -> Costa do Marfim | AG31: =VLOOKUP($AE31,$O$30:$X$33,3,FALSE) -> 6 | AH31: =VLOOKUP($AE31,$O$30:$X$33,4,FALSE) -> 3 | AI31: =VLOOKUP($AE31,$O$30:$X$33,5,FALSE) -> 2 | AJ31: =VLOOKUP($AE31,$O$30:$X$33,6,FALSE) -> 0 | AK31: =VLOOKUP($AE31,$O$30:$X$33,7,FALSE) -> 1 | AL31: =VLOOKUP($AE31,$O$30:$X$33,8,FALSE) -> 4 | AM31: =VLOOKUP($AE31,$O$30:$X$33,9,FALSE) -> 2 | AN31: =VLOOKUP($AE31,$O$30:$X$33,10,FALSE) -> 2 | AQ31: =CHAR(SMALL($AR$21:$AR$28,2)) -> D | AR31: =_xlfn.CONCAT(3,AQ31) -> 3D | AS31: =VLOOKUP(AQ31,$AZ$6:$BA$17,2,FALSE) -> Paraguai
B32: E | C32: 46198 | D32: 15.00 | E32: =P33 -> Equador | F32: 2 | G32: x | H32: 1 | I32: =P30 -> Alemanha | J32: =IF(F32=H32,"empate",IF(F32>H32,E32,I32)) -> Equador | K32: =IF(F32="","",IF(H32="","",IF(J32="empate",E32,""))) | L32: =IF(E32="","",IF(F32="","",IF(M32="empate",I32,""))) | M32: =IF(F32=H32,"empate",IF(F32<H32,E32,I32)) -> Alemanha | O32: =RANK(Q32,$Q$30:$Q$33)+SUM(Y32:AB32) -> 2 | P32: =Sorteios!F16 -> Costa do Marfim | Q32: =(S32*3)+(T32*1) -> 6 | R32: =SUM(S32:U32) -> 3 | S32: =COUNTIF(J:J,P32) -> 2 | T32: =COUNTIF(K:K,P32)+COUNTIF(L:L,P32) -> 0 | U32: =COUNTIF(M:M,P32) -> 1 | V32: =SUMIF(E:E,P32,F:F)+SUMIF(I:I,P32,H:H) -> 4 | W32: =SUMIF(E:E,P32,H:H)+SUMIF(I:I,P32,F:F) -> 2 | X32: =V32-W32 -> 2 | Y32: =SUMPRODUCT(($Q$30:$Q$33=Q32)*($X$30:$X$33>X32)) -> 1 | Z32: =SUMPRODUCT(($Q$30:$Q$33=Q32)*($X$30:$X$33=X32)*($V$30:$V$33>V32)) -> 0 | AA32: =SUMPRODUCT(($Q$30:$Q$33=Q32)*($X$30:$X$33=X32)*($V$30:$V$33=V32)*($W$30:$W$33>W32)) -> 0 | AB32: =SUMPRODUCT(($Q$30:$Q$33=Q32)*($X$30:$X$33=X32)*($V$30:$V$33=V32)*($W$30:$W$33=W32)*($AC$30:$AC$33<AC32)) -> 0 | AC32: 3 | AE32: 3 | AF32: =VLOOKUP($AE32,$O$30:$X$33,2,FALSE) -> Equador | AG32: =VLOOKUP($AE32,$O$30:$X$33,3,FALSE) -> 4 | AH32: =VLOOKUP($AE32,$O$30:$X$33,4,FALSE) -> 3 | AI32: =VLOOKUP($AE32,$O$30:$X$33,5,FALSE) -> 1 | AJ32: =VLOOKUP($AE32,$O$30:$X$33,6,FALSE) -> 1 | AK32: =VLOOKUP($AE32,$O$30:$X$33,7,FALSE) -> 1 | AL32: =VLOOKUP($AE32,$O$30:$X$33,8,FALSE) -> 2 | AM32: =VLOOKUP($AE32,$O$30:$X$33,9,FALSE) -> 2 | AN32: =VLOOKUP($AE32,$O$30:$X$33,10,FALSE) -> 0 | AQ32: =CHAR(SMALL($AR$21:$AR$28,3)) -> E | AR32: =_xlfn.CONCAT(3,AQ32) -> 3E | AS32: =VLOOKUP(AQ32,$AZ$6:$BA$17,2,FALSE) -> Equador
B33: E | C33: 46198 | D33: 15.00 | E33: =P31 -> Curaçau | F33: 0 | G33: x | H33: 2 | I33: =P32 -> Costa do Marfim | J33: =IF(F33=H33,"empate",IF(F33>H33,E33,I33)) -> Costa do Marfim | K33: =IF(F33="","",IF(H33="","",IF(J33="empate",E33,""))) | L33: =IF(E33="","",IF(F33="","",IF(M33="empate",I33,""))) | M33: =IF(F33=H33,"empate",IF(F33<H33,E33,I33)) -> Curaçau | O33: =RANK(Q33,$Q$30:$Q$33)+SUM(Y33:AB33) -> 3 | P33: =Sorteios!F17 -> Equador | Q33: =(S33*3)+(T33*1) -> 4 | R33: =SUM(S33:U33) -> 3 | S33: =COUNTIF(J:J,P33) -> 1 | T33: =COUNTIF(K:K,P33)+COUNTIF(L:L,P33) -> 1 | U33: =COUNTIF(M:M,P33) -> 1 | V33: =SUMIF(E:E,P33,F:F)+SUMIF(I:I,P33,H:H) -> 2 | W33: =SUMIF(E:E,P33,H:H)+SUMIF(I:I,P33,F:F) -> 2 | X33: =V33-W33 -> 0 | Y33: =SUMPRODUCT(($Q$30:$Q$33=Q33)*($X$30:$X$33>X33)) -> 0 | Z33: =SUMPRODUCT(($Q$30:$Q$33=Q33)*($X$30:$X$33=X33)*($V$30:$V$33>V33)) -> 0 | AA33: =SUMPRODUCT(($Q$30:$Q$33=Q33)*($X$30:$X$33=X33)*($V$30:$V$33=V33)*($W$30:$W$33>W33)) -> 0 | AB33: =SUMPRODUCT(($Q$30:$Q$33=Q33)*($X$30:$X$33=X33)*($V$30:$V$33=V33)*($W$30:$W$33=W33)*($AC$30:$AC$33<AC33)) -> 0 | AC33: 4 | AE33: 4 | AF33: =VLOOKUP($AE33,$O$30:$X$33,2,FALSE) -> Curaçau | AG33: =VLOOKUP($AE33,$O$30:$X$33,3,FALSE) -> 1 | AH33: =VLOOKUP($AE33,$O$30:$X$33,4,FALSE) -> 3 | AI33: =VLOOKUP($AE33,$O$30:$X$33,5,FALSE) -> 0 | AJ33: =VLOOKUP($AE33,$O$30:$X$33,6,FALSE) -> 1 | AK33: =VLOOKUP($AE33,$O$30:$X$33,7,FALSE) -> 2 | AL33: =VLOOKUP($AE33,$O$30:$X$33,8,FALSE) -> 1 | AM33: =VLOOKUP($AE33,$O$30:$X$33,9,FALSE) -> 9 | AN33: =VLOOKUP($AE33,$O$30:$X$33,10,FALSE) -> -8 | AQ33: =CHAR(SMALL($AR$21:$AR$28,4)) -> F | AR33: =_xlfn.CONCAT(3,AQ33) -> 3F | AS33: =VLOOKUP(AQ33,$AZ$6:$BA$17,2,FALSE) -> Suécia
B34: F | C34: 46187 | D34: 12.00 | E34: =P36 -> Países Baixos | F34: 2 | G34: x | H34: 2 | I34: =P37 -> Japão | J34: =IF(F34=H34,"empate",IF(F34>H34,E34,I34)) -> empate | K34: =IF(F34="","",IF(H34="","",IF(J34="empate",E34,""))) -> Países Baixos | L34: =IF(E34="","",IF(F34="","",IF(M34="empate",I34,""))) -> Japão | M34: =IF(F34=H34,"empate",IF(F34<H34,E34,I34)) -> empate | P34: Grupo F | AE34: Grupo F | AQ34: =CHAR(SMALL($AR$21:$AR$28,5)) -> I | AR34: =_xlfn.CONCAT(3,AQ34) -> 3I | AS34: =VLOOKUP(AQ34,$AZ$6:$BA$17,2,FALSE) -> Senegal
B35: F | C35: 46187 | D35: 09.00 | E35: =P38 -> Suécia | F35: 5 | G35: x | H35: 1 | I35: =P39 -> Tunísia | J35: =IF(F35=H35,"empate",IF(F35>H35,E35,I35)) -> Suécia | K35: =IF(F35="","",IF(H35="","",IF(J35="empate",E35,""))) | L35: =IF(E35="","",IF(F35="","",IF(M35="empate",I35,""))) | M35: =IF(F35=H35,"empate",IF(F35<H35,E35,I35)) -> Tunísia | O35: Rk | P35: Sorteio | Q35: Pontos | R35: Jogos | S35: Vit | T35: Emp | U35: Der | V35: GP | W35: GC | X35: SG | Y35: SAL | Z35: PRO | AA35: CON | AB35: NM | AC35: Or. | AE35: P. | AF35: Seleção | AG35: P | AH35: J | AI35: V | AJ35: E | AK35: D | AL35: GP | AM35: GC | AN35: SG | AQ35: =CHAR(SMALL($AR$21:$AR$28,6)) -> J | AR35: =_xlfn.CONCAT(3,AQ35) -> 3J | AS35: =VLOOKUP(AQ35,$AZ$6:$BA$17,2,FALSE) -> Argélia
B36: F | C36: 46193 | D36: 15.00 | E36: =P36 -> Países Baixos | F36: 5 | G36: x | H36: 1 | I36: =P38 -> Suécia | J36: =IF(F36=H36,"empate",IF(F36>H36,E36,I36)) -> Países Baixos | K36: =IF(F36="","",IF(H36="","",IF(J36="empate",E36,""))) | L36: =IF(E36="","",IF(F36="","",IF(M36="empate",I36,""))) | M36: =IF(F36=H36,"empate",IF(F36<H36,E36,I36)) -> Suécia | O36: =RANK(Q36,$Q$36:$Q$39)+SUM(Y36:AB36) -> 1 | P36: =Sorteios!I14 -> Países Baixos | Q36: =(S36*3)+(T36*1) -> 7 | R36: =SUM(S36:U36) -> 3 | S36: =COUNTIF(J:J,P36) -> 2 | T36: =COUNTIF(K:K,P36)+COUNTIF(L:L,P36) -> 1 | U36: =COUNTIF(M:M,P36) -> 0 | V36: =SUMIF(E:E,P36,F:F)+SUMIF(I:I,P36,H:H) -> 10 | W36: =SUMIF(E:E,P36,H:H)+SUMIF(I:I,P36,F:F) -> 4 | X36: =V36-W36 -> 6 | Y36: =SUMPRODUCT(($Q$36:$Q$39=Q36)*($X$36:$X$39>X36)) -> 0 | Z36: =SUMPRODUCT(($Q$36:$Q$39=Q36)*($X$36:$X$39=X36)*($V$36:$V$39>V36)) -> 0 | AA36: =SUMPRODUCT(($Q$36:$Q$39=Q36)*($X$36:$X$39=X36)*($V$36:$V$39=V36)*($W$36:$W$39>W36)) -> 0 | AB36: =SUMPRODUCT(($Q$36:$Q$39=Q36)*($X$36:$X$39=X36)*($V$36:$V$39=V36)*($W$36:$W$39=W36)*($AC$36:$AC$39<AC36)) -> 0 | AC36: 1 | AE36: 1 | AF36: =VLOOKUP($AE36,$O$36:$X$39,2,FALSE) -> Países Baixos | AG36: =VLOOKUP($AE36,$O$36:$X$39,3,FALSE) -> 7 | AH36: =VLOOKUP($AE36,$O$36:$X$39,4,FALSE) -> 3 | AI36: =VLOOKUP($AE36,$O$36:$X$39,5,FALSE) -> 2 | AJ36: =VLOOKUP($AE36,$O$36:$X$39,6,FALSE) -> 1 | AK36: =VLOOKUP($AE36,$O$36:$X$39,7,FALSE) -> 0 | AL36: =VLOOKUP($AE36,$O$36:$X$39,8,FALSE) -> 10 | AM36: =VLOOKUP($AE36,$O$36:$X$39,9,FALSE) -> 4 | AN36: =VLOOKUP($AE36,$O$36:$X$39,10,FALSE) -> 6 | AQ36: =CHAR(SMALL($AR$21:$AR$28,7)) -> K | AR36: =_xlfn.CONCAT(3,AQ36) -> 3K | AS36: =VLOOKUP(AQ36,$AZ$6:$BA$17,2,FALSE) -> RD Congo
